Workbook

Sheet 综合明细
A1: 2026复活节卡片分店综合明细及2027订货建议
A2: 每个分店名称合并覆盖5个卡片货号；按历史订单 Price 归为 $1、$2、$3 三档：$0.50归$1，$2.99归$3。
A3: 全部分店/卡片合计 | E3: ='2026进货数量'!G31 -> 16200 | F3: ='2026净销售数量'!G31 -> 9417 | G3: 1601 | H3: 5462 | I3: 2354 | J3: ='2026供应商退货'!G31 -> 3564 | K3: ='2027建议订货量'!G31 -> 10596 | L3: =K3-E3 -> -5604 | N3: $1 + $2 + $3 = 净销量 | O3: 3/26:282 3/27:292 3/28:243 3/29:201 3/30:409 3/31:471 4/1:505 ▅ ▅ ▄ ▄ ▇ █ █
A4: 分店名称 | B4: 卡片货号 | C4: 商品名称 | D4: 主要成交零售价 | E4: 进货数量 | F4: 销售数量（净） | G4: $1销量（含$0.50） | H4: $2销量 | I4: $3销量（含$2.99） | J4: 退供应商数量（季后库存） | K4: 2027订货建议 | L4: 建议较进货变化 | M4: Sean Ordered | N4: 原因分析 | O4: 最后7天日销量图（3/26–4/1）
A5: Robinson Road | B5: BEAC072 | C5: Deluxe Easter Card Stand 144 Pieces | D5: $2.00 | E5: ='2026进货数量'!B5 -> 144 | F5: ='2026净销售数量'!B5 -> 45 | G5: 0 | H5: 45 | I5: 0 | J5: ='2026供应商退货'!B5 -> 81 | K5: ='2027建议订货量'!B5 -> 0 | L5: =K5-E5 -> -144 | M5: 144 | N5: =建议原因!B5 -> 净销量45，不足半套72；建议0，由中央库存补货；2026退供应商81张（视为季后库存）；该货号整体退货率≥20%，谨慎减量 | O5: 3/26:1 3/27:4 3/28:2 3/29:0 3/30:6 3/31:1 4/1:4 ▂ ▆ ▃ · █ ▂ ▆
A6: Robinson Road | B6: EA258 | C6: World Greetings Easter Card Stand 144 Pieces | D6: $2.00 | E6: ='2026进货数量'!C5 -> 144 | F6: ='2026净销售数量'!C5 -> 62 | G6: 0 | H6: 62 | I6: 0 | J6: ='2026供应商退货'!C5 -> 70 | K6: ='2027建议订货量'!C5 -> 0 | L6: =K6-E6 -> -144 | N6: =建议原因!C5 -> 净销量62，不足半套72；建议0，由中央库存补货；2026退供应商70张（视为季后库存） | O6: 3/26:1 3/27:0 3/28:3 3/29:1 3/30:4 3/31:6 4/1:3 ▂ · ▄ ▂ ▆ █ ▄
A7: Robinson Road | B7: BEAC130 | C7: Elegance Easter Card Stand 144 Pieces | D7: $3（含$2.99/$3.00） | E7: ='2026进货数量'!D5 -> 144 | F7: ='2026净销售数量'!D5 -> 43 | G7: 0 | H7: 0 | I7: 43 | J7: ='2026供应商退货'!D5 -> 100 | K7: ='2027建议订货量'!D5 -> 0 | L7: =K7-E7 -> -144 | N7: =建议原因!D5 -> 净销量43，不足半套72；建议0，由中央库存补货；2026退供应商100张（视为季后库存）；该货号整体退货率≥20%，谨慎减量 | O7: 3/26:1 3/27:1 3/28:6 3/29:2 3/30:2 3/31:1 4/1:1 ▂ ▂ █ ▃ ▃ ▂ ▂
A8: Robinson Road | B8: BEAC071 | C8: Apsley Easter Card Stand 300 Pieces | D8: $1（含$0.50/$1.00） | E8: ='2026进货数量'!E5 -> 0 | F8: ='2026净销售数量'!E5 -> 0 | G8: 0 | H8: 0 | I8: 0 | J8: ='2026供应商退货'!E5 -> 0 | K8: ='2027建议订货量'!E5 -> 0 | L8: =K8-E8 -> 0 | N8: =建议原因!E5 -> 无净销量，建议0；先查现存库存及扫码映射 | O8: 3/26:0 3/27:0 3/28:0 3/29:0 3/30:0 3/31:0 4/1:0 · · · · · · ·
A9: Robinson Road | B9: EA256 | C9: Jordan Easter Card Stand 300 Pieces | D9: 混合：$1/$2 | E9: ='2026进货数量'!F5 -> 0 | F9: ='2026净销售数量'!F5 -> 0 | G9: 0 | H9: 0 | I9: 0 | J9: ='2026供应商退货'!F5 -> 0 | K9: ='2027建议订货量'!F5 -> 0 | L9: =K9-E9 -> 0 | N9: =建议原因!F5 -> 无净销量，建议0；先查现存库存及扫码映射 | O9: 3/26:0 3/27:0 3/28:0 3/29:0 3/30:0 3/31:0 4/1:0 · · · · · · ·
A10: Peninsula Fair | B10: BEAC072 | C10: Deluxe Easter Card Stand 144 Pieces | D10: $2.00 | E10: ='2026进货数量'!B6 -> 288 | F10: ='2026净销售数量'!B6 -> 207 | G10: 0 | H10: 207 | I10: 0 | J10: ='2026供应商退货'!B6 -> 79 | K10: ='2027建议订货量'!B6 -> 144 | L10: =K10-E10 -> -144 | M10: 432 | N10: =建议原因!B6 -> 按净销量207及包装规格，建议从2026进货288降至144；2026退供应商79张（视为季后库存）；该货号整体退货率≥20%，谨慎减量 | O10: 3/26:2 3/27:8 3/28:0 3/29:2 3/30:19 3/31:11 4/1:9 ▁ ▄ · ▁ █ ▅ ▄
A11: Peninsula Fair | B11: EA258 | C11: World Greetings Easter Card Stand 144 Pieces | D11: $2.00 | E11: ='2026进货数量'!C6 -> 288 | F11: ='2026净销售数量'!C6 -> 148 | G11: 0 | H11: 148 | I11: 0 | J11: ='2026供应商退货'!C6 -> 86 | K11: ='2027建议订货量'!C6 -> 144 | L11: =K11-E11 -> -144 | N11: =建议原因!C6 -> 按净销量148及包装规格，建议从2026进货288降至144；2026退供应商86张（视为季后库存） | O11: 3/26:11 3/27:6 3/28:3 3/29:1 3/30:14 3/31:14 4/1:8 ▇ ▄ ▂ ▁ █ █ ▅
A12: Peninsula Fair | B12: BEAC130 | C12: Elegance Easter Card Stand 144 Pieces | D12: $3（含$2.99/$3.00） | E12: ='2026进货数量'!D6 -> 144 | F12: ='2026净销售数量'!D6 -> 97 | G12: 0 | H12: 0 | I12: 97 | J12: ='2026供应商退货'!D6 -> 0 | K12: ='2027建议订货量'!D6 -> 144 | L12: =K12-E12 -> 0 | M12: 144 | N12: =建议原因!D6 -> 净销量97支持维持2026进货量；建议144；该货号整体退货率≥20%，谨慎减量 | O12: 3/26:1 3/27:3 3/28:2 3/29:4 3/30:3 3/31:3 4/1:1 ▂ ▆ ▄ █ ▆ ▆ ▂
A13: Peninsula Fair | B13: BEAC071 | C13: Apsley Easter Card Stand 300 Pieces | D13: $1（含$0.50/$1.00） | E13: ='2026进货数量'!E6 -> 0 | F13: ='2026净销售数量'!E6 -> 0 | G13: 0 | H13: 0 | I13: 0 | J13: ='2026供应商退货'!E6 -> 0 | K13: ='2027建议订货量'!E6 -> 0 | L13: =K13-E13 -> 0 | N13: =建议原因!E6 -> 无净销量，建议0；先查现存库存及扫码映射 | O13: 3/26:0 3/27:0 3/28:0 3/29:0 3/30:0 3/31:0 4/1:0 · · · · · · ·
A14: Peninsula Fair | B14: EA256 | C14: Jordan Easter Card Stand 300 Pieces | D14: 混合：$1/$2 | E14: ='2026进货数量'!F6 -> 0 | F14: ='2026净销售数量'!F6 -> 0 | G14: 0 | H14: 0 | I14: 0 | J14: ='2026供应商退货'!F6 -> 0 | K14: ='2027建议订货量'!F6 -> 0 | L14: =K14-E14 -> 0 | N14: =建议原因!F6 -> 无净销量，建议0；先查现存库存及扫码映射 | O14: 3/26:0 3/27:0 3/28:0 3/29:0 3/30:0 3/31:0 4/1:0 · · · · · · ·
A15: Campbelltown | B15: BEAC072 | C15: Deluxe Easter Card Stand 144 Pieces | D15: $2.00 | E15: ='2026进货数量'!B7 -> 144 | F15: ='2026净销售数量'!B7 -> 125 | G15: 0 | H15: 125 | I15: 0 | J15: ='2026供应商退货'!B7 -> 0 | K15: ='2027建议订货量'!B7 -> 144 | L15: =K15-E15 -> 0 | M15: 432 | N15: =建议原因!B7 -> 净销量125支持维持2026进货量；建议144；该货号整体退货率≥20%，谨慎减量 | O15: 3/26:1 3/27:0 3/28:1 3/29:0 3/30:3 3/31:0 4/1:1 ▃ · ▃ · █ · ▃
A16: Campbelltown | B16: EA258 | C16: World Greetings Easter Card Stand 144 Pieces | D16: $2.00 | E16: ='2026进货数量'!C7 -> 432 | F16: ='2026净销售数量'!C7 -> 273 | G16: 0 | H16: 273 | I16: 0 | J16: ='2026供应商退货'!C7 -> 125 | K16: ='2027建议订货量'!C7 -> 288 | L16: =K16-E16 -> -144 | N16: =建议原因!C7 -> 按净销量273及包装规格，建议从2026进货432降至288；2026退供应商125张（视为季后库存） | O16: 3/26:13 3/27:11 3/28:32 3/29:6 3/30:4 3/31:12 4/1:4 ▄ ▃ █ ▂ ▁ ▃ ▁
A17: Campbelltown | B17: BEAC130 | C17: Elegance Easter Card Stand 144 Pieces | D17: $3（含$2.99/$3.00） | E17: ='2026进货数量'!D7 -> 288 | F17: ='2026净销售数量'!D7 -> 167 | G17: 0 | H17: 0 | I17: 167 | J17: ='2026供应商退货'!D7 -> 73 | K17: ='2027建议订货量'!D7 -> 144 | L17: =K17-E17 -> -144 | M17: 288 | N17: =建议原因!D7 -> 按净销量167及包装规格，建议从2026进货288降至144；2026退供应商73张（视为季后库存）；该货号整体退货率≥20%，谨慎减量 | O17: 3/26:22 3/27:10 3/28:1 3/29:6 3/30:4 3/31:6 4/1:13 █ ▄ ▁ ▃ ▂ ▃ ▅
A18: Campbelltown | B18: BEAC071 | C18: Apsley Easter Card Stand 300 Pieces | D18: $1（含$0.50/$1.00） | E18: ='2026进货数量'!E7 -> 0 | F18: ='2026净销售数量'!E7 -> 0 | G18: 0 | H18: 0 | I18: 0 | J18: ='2026供应商退货'!E7 -> 0 | K18: ='2027建议订货量'!E7 -> 0 | L18: =K18-E18 -> 0 | N18: =建议原因!E7 -> 无净销量，建议0；先查现存库存及扫码映射 | O18: 3/26:0 3/27:0 3/28:0 3/29:0 3/30:0 3/31:0 4/1:0 · · · · · · ·
A19: Campbelltown | B19: EA256 | C19: Jordan Easter Card Stand 300 Pieces | D19: 混合：$1/$2 | E19: ='2026进货数量'!F7 -> 0 | F19: ='2026净销售数量'!F7 -> 0 | G19: 0 | H19: 0 | I19: 0 | J19: ='2026供应商退货'!F7 -> 0 | K19: ='2027建议订货量'!F7 -> 0 | L19: =K19-E19 -> 0 | N19: =建议原因!F7 -> 无净销量，建议0；先查现存库存及扫码映射 | O19: 3/26:0 3/27:0 3/28:0 3/29:0 3/30:0 3/31:0 4/1:0 · · · · · · ·
A20: Charlestown Square | B20: BEAC072 | C20: Deluxe Easter Card Stand 144 Pieces | D20: $2.00 | E20: ='2026进货数量'!B8 -> 288 | F20: ='2026净销售数量'!B8 -> 116 | G20: 0 | H20: 116 | I20: 0 | J20: ='2026供应商退货'!B8 -> 187 | K20: ='2027建议订货量'!B8 -> 144 | L20: =K20-E20 -> -144 | M20: 288 | N20: =建议原因!B8 -> 按净销量116及包装规格，建议从2026进货288降至144；2026退供应商187张（视为季后库存）；该货号整体退货率≥20%，谨慎减量 | O20: 3/26:2 3/27:2 3/28:1 3/29:3 3/30:4 3/31:7 4/1:13 ▂ ▂ ▁ ▂ ▃ ▅ █
A21: Charlestown Square | B21: EA258 | C21: World Greetings Easter Card Stand 144 Pieces | D21: $2.00 | E21: ='2026进货数量'!C8 -> 144 | F21: ='2026净销售数量'!C8 -> 63 | G21: 0 | H21: 63 | I21: 0 | J21: ='2026供应商退货'!C8 -> 0 | K21: ='2027建议订货量'!C8 -> 0 | L21: =K21-E21 -> -144 | N21: =建议原因!C8 -> 净销量63，不足半套72；建议0，由中央库存补货 | O21: 3/26:8 3/27:4 3/28:3 3/29:11 3/30:8 3/31:10 4/1:11 ▆ ▃ ▃ █ ▆ █ █
A22: Charlestown Square | B22: BEAC130 | C22: Elegance Easter Card Stand 144 Pieces | D22: $3（含$2.99/$3.00） | E22: ='2026进货数量'!D8 -> 288 | F22: ='2026净销售数量'!D8 -> 168 | G22: 0 | H22: 0 | I22: 168 | J22: ='2026供应商退货'!D8 -> 99 | K22: ='2027建议订货量'!D8 -> 144 | L22: =K22-E22 -> -144 | M22: 288 | N22: =建议原因!D8 -> 按净销量168及包装规格，建议从2026进货288降至144；2026退供应商99张（视为季后库存）；该货号整体退货率≥20%，谨慎减量 | O22: 3/26:13 3/27:7 3/28:3 3/29:4 3/30:1 3/31:11 4/1:6 █ ▅ ▂ ▃ ▁ ▇ ▄
A23: Charlestown Square | B23: BEAC071 | C23: Apsley Easter Card Stand 300 Pieces | D23: $1（含$0.50/$1.00） | E23: ='2026进货数量'!E8 -> 0 | F23: ='2026净销售数量'!E8 -> 0 | G23: 0 | H23: 0 | I23: 0 | J23: ='2026供应商退货'!E8 -> 0 | K23: ='2027建议订货量'!E8 -> 0 | L23: =K23-E23 -> 0 | N23: =建议原因!E8 -> 无净销量，建议0；先查现存库存及扫码映射 | O23: 3/26:0 3/27:0 3/28:0 3/29:0 3/30:0 3/31:0 4/1:0 · · · · · · ·
A24: Charlestown Square | B24: EA256 | C24: Jordan Easter Card Stand 300 Pieces | D24: 混合：$1/$2 | E24: ='2026进货数量'!F8 -> 0 | F24: ='2026净销售数量'!F8 -> 0 | G24: 0 | H24: 0 | I24: 0 | J24: ='2026供应商退货'!F8 -> 0 | K24: ='2027建议订货量'!F8 -> 0 | L24: =K24-E24 -> 0 | N24: =建议原因!F8 -> 无净销量，建议0；先查现存库存及扫码映射 | O24: 3/26:0 3/27:0 3/28:0 3/29:0 3/30:0 3/31:0 4/1:0 · · · · · · ·
A25: Jesmond | B25: BEAC072 | C25: Deluxe Easter Card Stand 144 Pieces | D25: $2.00 | E25: ='2026进货数量'!B9 -> 144 | F25: ='2026净销售数量'!B9 -> 65 | G25: 0 | H25: 65 | I25: 0 | J25: ='2026供应商退货'!B9 -> 66 | K25: ='2027建议订货量'!B9 -> 0 | L25: =K25-E25 -> -144 | M25: 144 | N25: =建议原因!B9 -> 净销量65，不足半套72；建议0，由中央库存补货；2026退供应商66张（视为季后库存）；该货号整体退货率≥20%，谨慎减量 | O25: 3/26:0 3/27:0 3/28:0 3/29:0 3/30:1 3/31:1 4/1:0 · · · · █ █ ·
A26: Jesmond | B26: EA258 | C26: World Greetings Easter Card Stand 144 Pieces | D26: $2.00 | E26: ='2026进货数量'!C9 -> 0 | F26: ='2026净销售数量'!C9 -> 0 | G26: 0 | H26: 0 | I26: 0 | J26: ='2026供应商退货'!C9 -> 0 | K26: ='2027建议订货量'!C9 -> 0 | L26: =K26-E26 -> 0 | N26: =建议原因!C9 -> 无净销量，建议0；先查现存库存及扫码映射 | O26: 3/26:0 3/27:0 3/28:0 3/29:0 3/30:0 3/31:0 4/1:0 · · · · · · ·
A27: Jesmond | B27: BEAC130 | C27: Elegance Easter Card Stand 144 Pieces | D27: $3（含$2.99/$3.00） | E27: ='2026进货数量'!D9 -> 288 | F27: ='2026净销售数量'!D9 -> 108 | G27: 0 | H27: 0 | I27: 108 | J27: ='2026供应商退货'!D9 -> 126 | K27: ='2027建议订货量'!D9 -> 144 | L27: =K27-E27 -> -144 | M27: 144 | N27: =建议原因!D9 -> 按净销量108及包装规格，建议从2026进货288降至144；2026退供应商126张（视为季后库存）；该货号整体退货率≥20%，谨慎减量 | O27: 3/26:2 3/27:0 3/28:4 3/29:0 3/30:1 3/31:4 4/1:2 ▄ · █ · ▂ █ ▄
A28: Jesmond | B28: BEAC071 | C28: Apsley Easter Card Stand 300 Pieces | D28: $1（含$0.50/$1.00） | E28: ='2026进货数量'!E9 -> 0 | F28: ='2026净销售数量'!E9 -> 0 | G28: 0 | H28: 0 | I28: 0 | J28: ='2026供应商退货'!E9 -> 0 | K28: ='2027建议订货量'!E9 -> 0 | L28: =K28-E28 -> 0 | N28: =建议原因!E9 -> 无净销量，建议0；先查现存库存及扫码映射 | O28: 3/26:0 3/27:0 3/28:0 3/29:0 3/30:0 3/31:0 4/1:0 · · · · · · ·
A29: Jesmond | B29: EA256 | C29: Jordan Easter Card Stand 300 Pieces | D29: 混合：$1/$2 | E29: ='2026进货数量'!F9 -> 0 | F29: ='2026净销售数量'!F9 -> 0 | G29: 0 | H29: 0 | I29: 0 | J29: ='2026供应商退货'!F9 -> 0 | K29: ='2027建议订货量'!F9 -> 0 | L29: =K29-E29 -> 0 | N29: =建议原因!F9 -> 无净销量，建议0；先查现存库存及扫码映射 | O29: 3/26:0 3/27:0 3/28:0 3/29:0 3/30:0 3/31:0 4/1:0 · · · · · · ·
A30: Pender Place | B30: BEAC072 | C30: Deluxe Easter Card Stand 144 Pieces | D30: $2.00 | E30: ='2026进货数量'!B10 -> 144 | F30: ='2026净销售数量'!B10 -> 126 | G30: 0 | H30: 126 | I30: 0 | J30: ='2026供应商退货'!B10 -> 111 | K30: ='2027建议订货量'!B10 -> 144 | L30: =K30-E30 -> 0 | M30: 288 | N30: =建议原因!B10 -> 净销量126支持维持2026进货量；建议144；2026退供应商111张（视为季后库存）；该货号整体退货率≥20%，谨慎减量 | O30: 3/26:7 3/27:2 3/28:2 3/29:12 3/30:6 3/31:2 4/1:9 ▅ ▂ ▂ █ ▄ ▂ ▆
A31: Pender Place | B31: EA258 | C31: World Greetings Easter Card Stand 144 Pieces | D31: $2.00 | E31: ='2026进货数量'!C10 -> 144 | F31: ='2026净销售数量'!C10 -> 126 | G31: 0 | H31: 126 | I31: 0 | J31: ='2026供应商退货'!C10 -> 0 | K31: ='2027建议订货量'!C10 -> 144 | L31: =K31-E31 -> 0 | N31: =建议原因!C10 -> 净销量126支持维持2026进货量；建议144 | O31: 3/26:0 3/27:5 3/28:3 3/29:12 3/30:12 3/31:5 4/1:2 · ▄ ▂ █ █ ▄ ▂
A32: Pender Place | B32: BEAC130 | C32: Elegance Easter Card Stand 144 Pieces | D32: $3（含$2.99/$3.00） | E32: ='2026进货数量'!D10 -> 0 | F32: ='2026净销售数量'!D10 -> 0 | G32: 0 | H32: 0 | I32: 0 | J32: ='2026供应商退货'!D10 -> 0 | K32: ='2027建议订货量'!D10 -> 0 | L32: =K32-E32 -> 0 | M32: 144 | N32: =建议原因!D10 -> 无净销量，建议0；先查现存库存及扫码映射；该货号整体退货率≥20%，谨慎减量 | O32: 3/26:0 3/27:0 3/28:0 3/29:0 3/30:0 3/31:0 4/1:0 · · · · · · ·
A33: Pender Place | B33: BEAC071 | C33: Apsley Easter Card Stand 300 Pieces | D33: $1（含$0.50/$1.00） | E33: ='2026进货数量'!E10 -> 0 | F33: ='2026净销售数量'!E10 -> 0 | G33: 0 | H33: 0 | I33: 0 | J33: ='2026供应商退货'!E10 -> 0 | K33: ='2027建议订货量'!E10 -> 0 | L33: =K33-E33 -> 0 | N33: =建议原因!E10 -> 无净销量，建议0；先查现存库存及扫码映射 | O33: 3/26:0 3/27:0 3/28:0 3/29:0 3/30:0 3/31:0 4/1:0 · · · · · · ·
A34: Pender Place | B34: EA256 | C34: Jordan Easter Card Stand 300 Pieces | D34: 混合：$1/$2 | E34: ='2026进货数量'!F10 -> 0 | F34: ='2026净销售数量'!F10 -> 0 | G34: 0 | H34: 0 | I34: 0 | J34: ='2026供应商退货'!F10 -> 0 | K34: ='2027建议订货量'!F10 -> 0 | L34: =K34-E34 -> 0 | N34: =建议原因!F10 -> 无净销量，建议0；先查现存库存及扫码映射 | O34: 3/26:0 3/27:0 3/28:0 3/29:0 3/30:0 3/31:0 4/1:0 · · · · · · ·
A35: Lake Haven | B35: BEAC072 | C35: Deluxe Easter Card Stand 144 Pieces | D35: $2.00 | E35: ='2026进货数量'!B11 -> 288 | F35: ='2026净销售数量'!B11 -> 151 | G35: 0 | H35: 151 | I35: 0 | J35: ='2026供应商退货'!B11 -> 0 | K35: ='2027建议订货量'!B11 -> 144 | L35: =K35-E35 -> -144 | M35: 288 | N35: =建议原因!B11 -> 按净销量151及包装规格，建议从2026进货288降至144；该货号整体退货率≥20%，谨慎减量 | O35: 3/26:6 3/27:3 3/28:7 3/29:0 3/30:9 3/31:7 4/1:11 ▅ ▃ ▆ · ▇ ▆ █
A36: Lake Haven | B36: EA258 | C36: World Greetings Easter Card Stand 144 Pieces | D36: $2.00 | E36: ='2026进货数量'!C11 -> 288 | F36: ='2026净销售数量'!C11 -> 99 | G36: 0 | H36: 99 | I36: 0 | J36: ='2026供应商退货'!C11 -> 178 | K36: ='2027建议订货量'!C11 -> 144 | L36: =K36-E36 -> -144 | N36: =建议原因!C11 -> 按净销量99及包装规格，建议从2026进货288降至144；2026退供应商178张（视为季后库存） | O36: 3/26:3 3/27:1 3/28:3 3/29:1 3/30:9 3/31:12 4/1:3 ▂ ▁ ▂ ▁ ▆ █ ▂
A37: Lake Haven | B37: BEAC130 | C37: Elegance Easter Card Stand 144 Pieces | D37: $3（含$2.99/$3.00） | E37: ='2026进货数量'!D11 -> 288 | F37: ='2026净销售数量'!D11 -> 132 | G37: 0 | H37: 0 | I37: 132 | J37: ='2026供应商退货'!D11 -> 113 | K37: ='2027建议订货量'!D11 -> 144 | L37: =K37-E37 -> -144 | M37: 288 | N37: =建议原因!D11 -> 按净销量132及包装规格，建议从2026进货288降至144；2026退供应商113张（视为季后库存）；该货号整体退货率≥20%，谨慎减量 | O37: 3/26:5 3/27:1 3/28:14 3/29:1 3/30:4 3/31:5 4/1:7 ▃ ▁ █ ▁ ▃ ▃ ▄
A38: Lake Haven | B38: BEAC071 | C38: Apsley Easter Card Stand 300 Pieces | D38: $1（含$0.50/$1.00） | E38: ='2026进货数量'!E11 -> 300 | F38: ='2026净销售数量'!E11 -> 322 | G38: 322 | H38: 0 | I38: 0 | J38: ='2026供应商退货'!E11 -> 0 | K38: ='2027建议订货量'!E11 -> 300 | L38: =K38-E38 -> 0 | M38: 300 | N38: =建议原因!E11 -> 净销量322支持维持2026进货量；建议300 | O38: 3/26:10 3/27:6 3/28:2 3/29:4 3/30:3 3/31:13 4/1:3 ▇ ▄ ▂ ▃ ▂ █ ▂
A39: Lake Haven | B39: EA256 | C39: Jordan Easter Card Stand 300 Pieces | D39: 混合：$1/$2 | E39: ='2026进货数量'!F11 -> 0 | F39: ='2026净销售数量'!F11 -> 47 | G39: 47 | H39: 0 | I39: 0 | J39: ='2026供应商退货'!F11 -> 0 | K39: ='2027建议订货量'!F11 -> 0 | L39: =K39-E39 -> 0 | N39: =建议原因!F11 -> 净销量47，不足半套150；建议0，由中央库存补货 | O39: 3/26:13 3/27:5 3/28:0 3/29:1 3/30:5 3/31:4 4/1:2 █ ▄ · ▁ ▄ ▃ ▂
A40: Forster | B40: BEAC072 | C40: Deluxe Easter Card Stand 144 Pieces | D40: $2.00 | E40: ='2026进货数量'!B12 -> 288 | F40: ='2026净销售数量'!B12 -> 177 | G40: 0 | H40: 177 | I40: 0 | J40: ='2026供应商退货'!B12 -> 0 | K40: ='2027建议订货量'!B12 -> 144 | L40: =K40-E40 -> -144 | M40: 288 | N40: =建议原因!B12 -> 按净销量177及包装规格，建议从2026进货288降至144；该货号整体退货率≥20%，谨慎减量 | O40: 3/26:4 3/27:3 3/28:13 3/29:2 3/30:2 3/31:8 4/1:7 ▃ ▂ █ ▂ ▂ ▅ ▅
...

Sheet Data
A1: Customer Customer Group Name | B1: Customer Code | C1: Customer Name | D1: Product Code | E1: Product Name | F1: INVOICE (Value) | G1: INVOICE (Quantity) | H1: CREDIT (Value) | I1: CREDIT (Quantity)
A2: Hot Bargain | B2: HOTBAWA | C2: HOT BARGAIN WARATAH | D2: BEAC130 | E2: Elegance Easter Card Stand 144 Pieces | F2: 345.62 | G2: 288 | H2: 0 | I2: 0
A3: Hot Bargain | B3: HOTBAWA | C3: HOT BARGAIN WARATAH | D3: BEAC072 | E3: Deluxe Easter Card Stand 144 Pieces | F3: 262.08 | G3: 288 | H3: 0 | I3: 0
A4: Hot Bargain | B4: HOTBAWA | C4: HOT BARGAIN WARATAH | D4: BEAC071 | E4: Apsley Easter Card Stand 300 Pieces | F4: 120 | G4: 300 | H4: 0 | I4: 0
A5: Hot Bargain | B5: HOTBAWA | C5: HOT BARGAIN WARATAH | D5: EA256 | E5: Jordan Easter Card Stand 300 Pieces | F5: 120 | G5: 300 | H5: 0 | I5: 0
A6: Hot Bargain | B6: HOTBAWA | C6: HOT BARGAIN WARATAH | D6: BEAC073 | E6: Deluxe Easter Pack - 50 Cards | F6: 45.5 | G6: 50 | H6: 0 | I6: 0
A7: Hot Bargain | B7: HOTBAWA | C7: HOT BARGAIN WARATAH | D7: BEAC131 | E7: Elegance Easter Pack - 24 Cards | F7: 28.8 | G7: 24 | H7: 0 | I7: 0
A8: Hot Bargain | B8: HOTBAWA | C8: HOT BARGAIN WARATAH | D8: EA289 | E8: Easter Gift Bag Jumbo - Assorted | F8: 27.36 | G8: 24 | H8: 0 | I8: 0
A9: Hot Bargain | B9: HOTBAWA | C9: HOT BARGAIN WARATAH | D9: EA288 | E9: Easter Gift Bag Large - Assorted | F9: 21.84 | G9: 24 | H9: 0 | I9: 0
A10: Hot Bargain | B10: HOTBAWA | C10: HOT BARGAIN WARATAH | D10: EA287 | E10: Easter Gift Bag Medium - Assorted | F10: 11.28 | G10: 24 | H10: 0 | I10: 0
A11: Hot Bargain | B11: HOTBAWA | C11: HOT BARGAIN WARATAH | D11: EA286 | E11: Easter Gift Bag Small - Assorted | F11: 8.16 | G11: 24 | H11: 0 | I11: 0
A12: Hot Bargain | B12: HOTBCR | C12: HOT BARGAIN CRONULLA | D12: EA069 | E12: Easter Cello Roll Wrap 3mx760mm | F12: 273 | G12: 150 | H12: 0 | I12: 0
A13: Hot Bargain | B13: HOTBCR | C13: HOT BARGAIN CRONULLA | D13: EA256 | E13: Jordan Easter Card Stand 300 Pieces | F13: 120 | G13: 300 | H13: 0 | I13: 0
... A82: Hot Bargain | B82: HOTMAT | C82: HOT BARGAIN MAITLAND | D82: BEAC072 | E82: Deluxe Easter Card Stand 144 Pieces | F82: 131.04 | G82: 144 | H82: -101.01 | I82: -111

Sheet Query
A1: Date Exported | B1: 46149.591
A2: Last Verified | B2: 46149.174
A3: User | B3: christap
A4: Database | B4: ARTWRAP Sales
A5: Mode | B5: Matrix
A6: Measures | B6: Value
B7: Quantity
A8: Dimension | B8: Product
A9: Filter | B9: Sales Only
A10: Format | B10: Actual
A11: Stream | B11: Sales
A12: Period | B12: Sep 2025 – May 2026
A13: Matrix | B13: Transaction Type
B14: INVOICE ()
B15: CREDIT ()
A16: Selections | B16: Customer Group
B17: Selected (2)
B18: 276 (Hot Bargain)
B19: 471 (Hot Bargain - Leo)
B20: Product Catalogue
B21: Selected (1)
B22: Easter ()

Sheet 高峰与库存判断
A1: 2026复活节卡片分店销售高峰与库存充足度判断
A2: 销售统计截止2026-04-01；复活节周一为2026-04-06。判断基于5个货号合计、Excel进货（缺失时用HBweb补充）、净销量及退供应商季后库存；调拨和期初库存无历史快照，结论为风险推断。
A4: 分店名称 | B4: 高峰销售日 | C4: 复活节周一前几天 | D4: 高峰日销量 | E4: 峰前累计销量 | F4: 峰后销量 | G4: 最后销售日 | H4: 已知进货量 | I4: 季后库存/退供应商 | J4: 总净销量 | K4: 估算剩余 | L4: 库存判断 | M4: 判断原因
A5: Robinson Road | B5: 2026-03-20 | C5: 17 | D5: 19 | E5: 59 | F5: 72 | G5: 2026-04-01 | H5: 432 | I5: 251 | J5: 150 | K5: 282 | L5: 数量足够 | M5: 季后库存251张≥单日峰值19张，未见整体数量不足
A6: Peninsula Fair | B6: 2026-03-30 | C6: 7 | D6: 36 | E6: 370 | F6: 46 | G6: 2026-04-01 | H6: 720 | I6: 165 | J6: 452 | K6: 268 | L6: 数量足够 | M6: 季后库存165张≥单日峰值36张，未见整体数量不足
A7: Campbelltown | B7: 2026-03-26 | C7: 11 | D7: 36 | E7: 415 | F7: 114 | G7: 2026-04-01 | H7: 864 | I7: 198 | J7: 565 | K7: 299 | L7: 数量足够 | M7: 季后库存198张≥单日峰值36张，未见整体数量不足
A8: Charlestown Square | B8: 2026-04-01 | C8: 5 | D8: 30 | E8: 317 | F8: 0 | G8: 2026-04-01 | H8: 720 | I8: 286 | J8: 347 | K8: 373 | L8: 数量足够 | M8: 季后库存286张≥单日峰值30张，未见整体数量不足
A9: Jesmond | B9: 2026-03-02 | C9: 35 | D9: 17 | E9: 55 | F9: 101 | G9: 2026-04-01 | H9: 432 | I9: 192 | J9: 173 | K9: 259 | L9: 数量足够 | M9: 季后库存192张≥单日峰值17张，未见整体数量不足
A10: Pender Place | B10: 2026-03-29 | C10: 8 | D10: 24 | E10: 192 | F10: 36 | G10: 2026-04-01 | H10: 288 | I10: 111 | J10: 252 | K10: 36 | L10: 数量足够 | M10: 季后库存111张≥单日峰值24张，未见整体数量不足
A11: Lake Haven | B11: 2026-03-31 | C11: 6 | D11: 41 | E11: 684 | F11: 26 | G11: 2026-04-01 | H11: 1164 | I11: 291 | J11: 751 | K11: 413 | L11: 数量足够 | M11: 季后库存291张≥单日峰值41张，未见整体数量不足
A12: Forster | B12: 2026-03-28 | C12: 9 | D12: 17 | E12: 229 | F12: 44 | G12: 2026-04-01 | H12: 576 | I12: 0 | J12: 290 | K12: 286 | L12: 大概率足够 | M12: 估算余量286张可覆盖约16.8个峰值日
A13: Glendale | B13: 2026-03-20 | C13: 17 | D13: 28 | E13: 311 | F13: 164 | G13: 2026-04-01 | H13: 720 | I13: 159 | J13: 503 | K13: 217 | L13: 数量足够 | M13: 季后库存159张≥单日峰值28张，未见整体数量不足
A14: Orion | B14: 2026-02-18 | C14: 47 | D14: 18 | E14: 0 | F14: 242 | G14: 2026-04-01 | H14: 1152 | I14: 841 | J14: 260 | K14: 892 | L14: 数量足够 | M14: 季后库存841张≥单日峰值18张，未见整体数量不足
A15: Kawana | B15: 2026-02-26 | C15: 39 | D15: 36 | E15: 69 | F15: 334 | G15: 2026-04-01 | H15: 720 | I15: 0 | J15: 439 | K15: 281 | L15: 大概率足够 | M15: 估算余量281张可覆盖约7.8个峰值日
A16: Cronulla | B16: 2026-04-01 | C16: 5 | D16: 72 | E16: 536 | F16: 0 | G16: 2026-04-01 | H16: 1164 | I16: 685 | J16: 608 | K16: 556 | L16: 数量足够 | M16: 季后库存685张≥单日峰值72张，未见整体数量不足
... A28: Top Ryde | B28: 2026-03-13 | C28: 24 | D28: 28 | E28: 266 | F28: 231 | G28: 2026-04-01 | H28: 576 | I28: 9 | J28: 525 | K28: 51 | L28: 偏紧 | M28: 季后库存仅9张，低于峰值日28张；仍销售至2026-04-01
A29: Discount General Charlestown | D29: 0 | E29: 0 | F29: 0 | H29: 432 | I29: 0 | J29: 0 | K29: 432 | L29: 无销量数据 | M29: HBweb无对应销售；未映射门店或中央库存无法按销售高峰判断
A30: HB Warehouse | D30: 0 | E30: 0 | F30: 0 | H30: 588 | I30: 0 | J30: 0 | K30: 588 | L30: 无销量数据 | M30: HBweb无对应销售；未映射门店或中央库存无法按销售高峰判断
A31: 全公司合计/峰值 | B31: 2026-04-01 | C31: 5 | D31: 505 | G31: 2026-04-01 | H31: 16488 | I31: 3564 | J31: 9417 | K31: 7071 | L31: 总体足够，局部分店偏紧 | M31: 截至4月1日，全公司最高峰为4月1日（复活节周一前5天）；季后回收库存高于全公司单日峰值，但需关注分店及货号分布

Sheet 进货对账
A1: Art Wrap复活节卡片：数据库与Excel进货数量对账 | G1: 按货号对账
A2: Excel来源：供应商报表 INVOICE (Quantity)；数据库来源：HBweb StoreLocalSupplierInvoice/Details，供应商250，2025-09-01至2026-05-31。
A4: 分店名称 | B4: Excel进货 | C4: HBweb数据库进货 | D4: 数据库-Excel差异 | E4: 对账结论 | G4: 货号 | H4: Excel进货 | I4: HBweb数据库进货 | J4: 数据库-Excel差异 | K4: 数据库覆盖率 | L4: 结论
A5: Robinson Road | B5: ='2026进货数量'!G5 -> 432 | C5: 432 | D5: =C5-B5 -> 0 | E5: =IF(D5=0,"匹配",IF(B5=0,"数据库多出",IF(C5=0,"数据库缺失","部分匹配"))) -> 匹配 | G5: BEAC072 | H5: 5328 | I5: 1584 | J5: =I5-H5 -> -3744 | K5: =IF(H5=0,0,I5/H5) -> 0.2972973 | L5: =IF(J5=0,"匹配","不匹配") -> 不匹配
A6: Peninsula Fair | B6: ='2026进货数量'!G6 -> 720 | C6: 720 | D6: =C6-B6 -> 0 | E6: =IF(D6=0,"匹配",IF(B6=0,"数据库多出",IF(C6=0,"数据库缺失","部分匹配"))) -> 匹配 | G6: EA258 | H6: 4032 | I6: 1584 | J6: =I6-H6 -> -2448 | K6: =IF(H6=0,0,I6/H6) -> 0.39285714 | L6: =IF(J6=0,"匹配","不匹配") -> 不匹配
A7: Campbelltown | B7: ='2026进货数量'!G7 -> 864 | C7: 864 | D7: =C7-B7 -> 0 | E7: =IF(D7=0,"匹配",IF(B7=0,"数据库多出",IF(C7=0,"数据库缺失","部分匹配"))) -> 匹配 | G7: BEAC130 | H7: 5040 | I7: 1872 | J7: =I7-H7 -> -3168 | K7: =IF(H7=0,0,I7/H7) -> 0.37142857 | L7: =IF(J7=0,"匹配","不匹配") -> 不匹配
A8: Charlestown Square | B8: ='2026进货数量'!G8 -> 720 | C8: 720 | D8: =C8-B8 -> 0 | E8: =IF(D8=0,"匹配",IF(B8=0,"数据库多出",IF(C8=0,"数据库缺失","部分匹配"))) -> 匹配 | G8: BEAC071 | H8: 1200 | I8: 300 | J8: =I8-H8 -> -900 | K8: =IF(H8=0,0,I8/H8) -> 0.25 | L8: =IF(J8=0,"匹配","不匹配") -> 不匹配
A9: Jesmond | B9: ='2026进货数量'!G9 -> 432 | C9: 0 | D9: =C9-B9 -> -432 | E9: =IF(D9=0,"匹配",IF(B9=0,"数据库多出",IF(C9=0,"数据库缺失","部分匹配"))) -> 数据库缺失 | G9: EA256 | H9: 600 | I9: 0 | J9: =I9-H9 -> -600 | K9: =IF(H9=0,0,I9/H9) -> 0 | L9: =IF(J9=0,"匹配","不匹配") -> 不匹配
A10: Pender Place | B10: ='2026进货数量'!G10 -> 288 | C10: 0 | D10: =C10-B10 -> -288 | E10: =IF(D10=0,"匹配",IF(B10=0,"数据库多出",IF(C10=0,"数据库缺失","部分匹配"))) -> 数据库缺失 | G10: 全部货号合计 | H10: 16200 | I10: 5340 | J10: =I10-H10 -> -10860 | K10: =IF(H10=0,0,I10/H10) -> 0.32962963 | L10: 数据库仅部分覆盖
A11: Lake Haven | B11: ='2026进货数量'!G11 -> 1164 | C11: 1164 | D11: =C11-B11 -> 0 | E11: =IF(D11=0,"匹配",IF(B11=0,"数据库多出",IF(C11=0,"数据库缺失","部分匹配"))) -> 匹配
A12: Forster | B12: ='2026进货数量'!G12 -> 576 | C12: 0 | D12: =C12-B12 -> -576 | E12: =IF(D12=0,"匹配",IF(B12=0,"数据库多出",IF(C12=0,"数据库缺失","部分匹配"))) -> 数据库缺失
A13: Glendale | B13: ='2026进货数量'!G13 -> 720 | C13: 0 | D13: =C13-B13 -> -720 | E13: =IF(D13=0,"匹配",IF(B13=0,"数据库多出",IF(C13=0,"数据库缺失","部分匹配"))) -> 数据库缺失 | G13: 重要发现
A14: Orion | B14: ='2026进货数量'!G14 -> 1152 | C14: 0 | D14: =C14-B14 -> -1152 | E14: =IF(D14=0,"匹配",IF(B14=0,"数据库多出",IF(C14=0,"数据库缺失","部分匹配"))) -> 数据库缺失 | G14: 数据库覆盖 | H14: 5,340 / 16,200 = 33.0%，不能替代Excel作为完整进货来源
A15: Kawana | B15: ='2026进货数量'!G15 -> 720 | C15: 720 | D15: =C15-B15 -> 0 | E15: =IF(D15=0,"匹配",IF(B15=0,"数据库多出",IF(C15=0,"数据库缺失","部分匹配"))) -> 匹配 | G15: 完全匹配门店 | H15: Robinson Road、Peninsula Fair、Campbelltown、Charlestown Square、Lake Haven、Kawana
A16: Cronulla | B16: ='2026进货数量'!G16 -> 1164 | C16: 0 | D16: =C16-B16 -> -1164 | E16: =IF(D16=0,"匹配",IF(B16=0,"数据库多出",IF(C16=0,"数据库缺失","部分匹配"))) -> 数据库缺失 | G16: 部分匹配 | H16: Top Ryde：BEAC130匹配；BEAC072数据库144张、Excel 288张，少144张
A17: Greenhills | B17: ='2026进货数量'!G17 -> 576 | C17: 0 | D17: =C17-B17 -> -576 | E17: =IF(D17=0,"匹配",IF(B17=0,"数据库多出",IF(C17=0,"数据库缺失","部分匹配"))) -> 数据库缺失 | G17: 数据库多出 | H17: Tuggerah：BEAC072 144张、BEAC130 144张；Excel无对应进货
A18: Waratah | B18: ='2026进货数量'!G18 -> 1176 | C18: 0 | D18: =C18-B18 -> -1176 | E18: =IF(D18=0,"匹配",IF(B18=0,"数据库多出",IF(C18=0,"数据库缺失","部分匹配"))) -> 数据库缺失 | G18: 数据库缺口 | H18: Excel有而数据库缺失/少记11,148张；数据库额外288张；最终净少10,860张
A19: Toukley | B19: ='2026进货数量'!G19 -> 288 | C19: 0 | D19: =C19-B19 -> -288 | E19: =IF(D19=0,"匹配",IF(B19=0,"数据库多出",IF(C19=0,"数据库缺失","部分匹配"))) -> 数据库缺失 | G19: 单据状态 | H19: 数据库共13张相关进货单；FlowStatus 1或3，InboundStatus均为0，InboundDate为空
A20: Warners Bay | B20: ='2026进货数量'!G20 -> 432 | C20: 0 | D20: =C20-B20 -> -432 | E20: =IF(D20=0,"匹配",IF(B20=0,"数据库多出",IF(C20=0,"数据库缺失","部分匹配"))) -> 数据库缺失
A21: Wallsend | B21: ='2026进货数量'!G21 -> 588 | C21: 0 | D21: =C21-B21 -> -588 | E21: =IF(D21=0,"匹配",IF(B21=0,"数据库多出",IF(C21=0,"数据库缺失","部分匹配"))) -> 数据库缺失
A22: Raymond Terrace | B22: ='2026进货数量'!G22 -> 0 | C22: 0 | D22: =C22-B22 -> 0 | E22: =IF(D22=0,"匹配",IF(B22=0,"数据库多出",IF(C22=0,"数据库缺失","部分匹配"))) -> 匹配
A23: Oran Park | B23: ='2026进货数量'!G23 -> 720 | C23: 0 | D23: =C23-B23 -> -720 | E23: =IF(D23=0,"匹配",IF(B23=0,"数据库多出",IF(C23=0,"数据库缺失","部分匹配"))) -> 数据库缺失
A24: Bankstown | B24: ='2026进货数量'!G24 -> 432 | C24: 0 | D24: =C24-B24 -> -432 | E24: =IF(D24=0,"匹配",IF(B24=0,"数据库多出",IF(C24=0,"数据库缺失","部分匹配"))) -> 数据库缺失
A25: Tuggerah | B25: ='2026进货数量'!G25 -> 0 | C25: 288 | D25: =C25-B25 -> 288 | E25: =IF(D25=0,"匹配",IF(B25=0,"数据库多出",IF(C25=0,"数据库缺失","部分匹配"))) -> 数据库多出
A26: Kotara | B26: ='2026进货数量'!G26 -> 864 | C26: 0 | D26: =C26-B26 -> -864 | E26: =IF(D26=0,"匹配",IF(B26=0,"数据库多出",IF(C26=0,"数据库缺失","部分匹配"))) -> 数据库缺失
A27: Southport Park | B27: ='2026进货数量'!G27 -> 576 | C27: 0 | D27: =C27-B27 -> -576 | E27: =IF(D27=0,"匹配",IF(B27=0,"数据库多出",IF(C27=0,"数据库缺失","部分匹配"))) -> 数据库缺失
A28: Top Ryde | B28: ='2026进货数量'!G28 -> 576 | C28: 432 | D28: =C28-B28 -> -144 | E28: =IF(D28=0,"匹配",IF(B28=0,"数据库多出",IF(C28=0,"数据库缺失","部分匹配"))) -> 部分匹配
A29: Discount General Charlestown | B29: ='2026进货数量'!G29 -> 432 | C29: 0 | D29: =C29-B29 -> -432 | E29: =IF(D29=0,"匹配",IF(B29=0,"数据库多出",IF(C29=0,"数据库缺失","部分匹配"))) -> 数据库缺失
A30: HB Warehouse | B30: ='2026进货数量'!G30 -> 588 | C30: 0 | D30: =C30-B30 -> -588 | E30: =IF(D30=0,"匹配",IF(B30=0,"数据库多出",IF(C30=0,"数据库缺失","部分匹配"))) -> 数据库缺失
A31: 全部分店合计 | B31: =SUM(B5:B30) -> 16200 | C31: =SUM(C5:C30) -> 5340 | D31: =C31-B31 -> -10860 | E31: =IF(D31=0,"全部匹配","数据库仅部分覆盖") -> 数据库仅部分覆盖

Sheet 售价销量汇总
A1: 2026复活节卡片按零售价销量汇总（跨货号） | I1: 按货号的零售价销量
A2: 按POSM订单明细 Price 归为三档：$0.50/$1.00归$1，$2.00归$2，$2.99/$3.00归$3；折扣订单仍按原零售价归档。
A4: 分店名称 | B4: $1销量 | C4: $2销量 | D4: $3销量 | E4: 全部净销量 | F4: $1占比 | G4: $2占比 | I4: 货号 | J4: $1销量 | K4: $2销量 | L4: $3销量 | M4: 全部净销量 | N4: 主要成交零售价
A5: Robinson Road | B5: =SUM(综合明细!G5:G9) -> 0 | C5: =SUM(综合明细!H5:H9) -> 107 | D5: =SUM(综合明细!I5:I9) -> 43 | E5: =SUM(B5:D5) -> 150 | F5: =IF(E5=0,0,B5/E5) -> 0 | G5: =IF(E5=0,0,C5/E5) -> 0.71333333 | I5: BEAC072 | J5: =SUMIF(综合明细!$B$5:$B$134,I5,综合明细!$G$5:$G$134) -> 0 | K5: =SUMIF(综合明细!$B$5:$B$134,I5,综合明细!$H$5:$H$134) -> 3067 | L5: =SUMIF(综合明细!$B$5:$B$134,I5,综合明细!$I$5:$I$134) -> 0 | M5: =SUM(J5:L5) -> 3067 | N5: $2.00
A6: Peninsula Fair | B6: =SUM(综合明细!G10:G14) -> 0 | C6: =SUM(综合明细!H10:H14) -> 355 | D6: =SUM(综合明细!I10:I14) -> 97 | E6: =SUM(B6:D6) -> 452 | F6: =IF(E6=0,0,B6/E6) -> 0 | G6: =IF(E6=0,0,C6/E6) -> 0.78539823 | I6: EA258 | J6: =SUMIF(综合明细!$B$5:$B$134,I6,综合明细!$G$5:$G$134) -> 0 | K6: =SUMIF(综合明细!$B$5:$B$134,I6,综合明细!$H$5:$H$134) -> 2391 | L6: =SUMIF(综合明细!$B$5:$B$134,I6,综合明细!$I$5:$I$134) -> 0 | M6: =SUM(J6:L6) -> 2391 | N6: $2.00
A7: Campbelltown | B7: =SUM(综合明细!G15:G19) -> 0 | C7: =SUM(综合明细!H15:H19) -> 398 | D7: =SUM(综合明细!I15:I19) -> 167 | E7: =SUM(B7:D7) -> 565 | F7: =IF(E7=0,0,B7/E7) -> 0 | G7: =IF(E7=0,0,C7/E7) -> 0.70442478 | I7: BEAC130 | J7: =SUMIF(综合明细!$B$5:$B$134,I7,综合明细!$G$5:$G$134) -> 0 | K7: =SUMIF(综合明细!$B$5:$B$134,I7,综合明细!$H$5:$H$134) -> 0 | L7: =SUMIF(综合明细!$B$5:$B$134,I7,综合明细!$I$5:$I$134) -> 2354 | M7: =SUM(J7:L7) -> 2354 | N7: $3（含$2.99/$3.00）
A8: Charlestown Square | B8: =SUM(综合明细!G20:G24) -> 0 | C8: =SUM(综合明细!H20:H24) -> 179 | D8: =SUM(综合明细!I20:I24) -> 168 | E8: =SUM(B8:D8) -> 347 | F8: =IF(E8=0,0,B8/E8) -> 0 | G8: =IF(E8=0,0,C8/E8) -> 0.51585014 | I8: BEAC071 | J8: =SUMIF(综合明细!$B$5:$B$134,I8,综合明细!$G$5:$G$134) -> 1285 | K8: =SUMIF(综合明细!$B$5:$B$134,I8,综合明细!$H$5:$H$134) -> 0 | L8: =SUMIF(综合明细!$B$5:$B$134,I8,综合明细!$I$5:$I$134) -> 0 | M8: =SUM(J8:L8) -> 1285 | N8: $1（含$0.50/$1.00）
A9: Jesmond | B9: =SUM(综合明细!G25:G29) -> 0 | C9: =SUM(综合明细!H25:H29) -> 65 | D9: =SUM(综合明细!I25:I29) -> 108 | E9: =SUM(B9:D9) -> 173 | F9: =IF(E9=0,0,B9/E9) -> 0 | G9: =IF(E9=0,0,C9/E9) -> 0.37572254 | I9: EA256 | J9: =SUMIF(综合明细!$B$5:$B$134,I9,综合明细!$G$5:$G$134) -> 316 | K9: =SUMIF(综合明细!$B$5:$B$134,I9,综合明细!$H$5:$H$134) -> 4 | L9: =SUMIF(综合明细!$B$5:$B$134,I9,综合明细!$I$5:$I$134) -> 0 | M9: =SUM(J9:L9) -> 320 | N9: 混合：$1/$2
A10: Pender Place | B10: =SUM(综合明细!G30:G34) -> 0 | C10: =SUM(综合明细!H30:H34) -> 252 | D10: =SUM(综合明细!I30:I34) -> 0 | E10: =SUM(B10:D10) -> 252 | F10: =IF(E10=0,0,B10/E10) -> 0 | G10: =IF(E10=0,0,C10/E10) -> 1 | I10: 全部货号合计 | J10: =SUM(J5:J9) -> 1601 | K10: =SUM(K5:K9) -> 5462 | L10: =SUM(L5:L9) -> 2354 | M10: =SUM(M5:M9) -> 9417 | N10: 三档合计应等于净销量
A11: Lake Haven | B11: =SUM(综合明细!G35:G39) -> 369 | C11: =SUM(综合明细!H35:H39) -> 250 | D11: =SUM(综合明细!I35:I39) -> 132 | E11: =SUM(B11:D11) -> 751 | F11: =IF(E11=0,0,B11/E11) -> 0.49134487 | G11: =IF(E11=0,0,C11/E11) -> 0.33288948
A12: Forster | B12: =SUM(综合明细!G40:G44) -> 0 | C12: =SUM(综合明细!H40:H44) -> 290 | D12: =SUM(综合明细!I40:I44) -> 0 | E12: =SUM(B12:D12) -> 290 | F12: =IF(E12=0,0,B12/E12) -> 0 | G12: =IF(E12=0,0,C12/E12) -> 1
A13: Glendale | B13: =SUM(综合明细!G45:G49) -> 0 | C13: =SUM(综合明细!H45:H49) -> 342 | D13: =SUM(综合明细!I45:I49) -> 161 | E13: =SUM(B13:D13) -> 503 | F13: =IF(E13=0,0,B13/E13) -> 0 | G13: =IF(E13=0,0,C13/E13) -> 0.67992048
A14: Orion | B14: =SUM(综合明细!G50:G54) -> 0 | C14: =SUM(综合明细!H50:H54) -> 166 | D14: =SUM(综合明细!I50:I54) -> 94 | E14: =SUM(B14:D14) -> 260 | F14: =IF(E14=0,0,B14/E14) -> 0 | G14: =IF(E14=0,0,C14/E14) -> 0.63846154
A15: Kawana | B15: =SUM(综合明细!G55:G59) -> 0 | C15: =SUM(综合明细!H55:H59) -> 270 | D15: =SUM(综合明细!I55:I59) -> 169 | E15: =SUM(B15:D15) -> 439 | F15: =IF(E15=0,0,B15/E15) -> 0 | G15: =IF(E15=0,0,C15/E15) -> 0.61503417
A16: Cronulla | B16: =SUM(综合明细!G60:G64) -> 250 | C16: =SUM(综合明细!H60:H64) -> 238 | D16: =SUM(综合明细!I60:I64) -> 120 | E16: =SUM(B16:D16) -> 608 | F16: =IF(E16=0,0,B16/E16) -> 0.41118421 | G16: =IF(E16=0,0,C16/E16) -> 0.39144737
A17: Greenhills | B17: =SUM(综合明细!G65:G69) -> 0 | C17: =SUM(综合明细!H65:H69) -> 154 | D17: =SUM(综合明细!I65:I69) -> 91 | E17: =SUM(B17:D17) -> 245 | F17: =IF(E17=0,0,B17/E17) -> 0 | G17: =IF(E17=0,0,C17/E17) -> 0.62857143
A18: Waratah | B18: =SUM(综合明细!G70:G74) -> 393 | C18: =SUM(综合明细!H70:H74) -> 218 | D18: =SUM(综合明细!I70:I74) -> 165 | E18: =SUM(B18:D18) -> 776 | F18: =IF(E18=0,0,B18/E18) -> 0.5064433 | G18: =IF(E18=0,0,C18/E18) -> 0.28092784
A19: Toukley | B19: =SUM(综合明细!G75:G79) -> 0 | C19: =SUM(综合明细!H75:H79) -> 243 | D19: =SUM(综合明细!I75:I79) -> 0 | E19: =SUM(B19:D19) -> 243 | F19: =IF(E19=0,0,B19/E19) -> 0 | G19: =IF(E19=0,0,C19/E19) -> 1
A20: Warners Bay | B20: =SUM(综合明细!G80:G84) -> 0 | C20: =SUM(综合明细!H80:H84) -> 248 | D20: =SUM(综合明细!I80:I84) -> 100 | E20: =SUM(B20:D20) -> 348 | F20: =IF(E20=0,0,B20/E20) -> 0 | G20: =IF(E20=0,0,C20/E20) -> 0.71264368
A21: Wallsend | B21: =SUM(综合明细!G85:G89) -> 298 | C21: =SUM(综合明细!H85:H89) -> 197 | D21: =SUM(综合明细!I85:I89) -> 16 | E21: =SUM(B21:D21) -> 511 | F21: =IF(E21=0,0,B21/E21) -> 0.58317025 | G21: =IF(E21=0,0,C21/E21) -> 0.38551859
A22: Raymond Terrace | B22: =SUM(综合明细!G90:G94) -> 291 | C22: =SUM(综合明细!H90:H94) -> 235 | D22: =SUM(综合明细!I90:I94) -> 0 | E22: =SUM(B22:D22) -> 526 | F22: =IF(E22=0,0,B22/E22) -> 0.55323194 | G22: =IF(E22=0,0,C22/E22) -> 0.44676806
A23: Oran Park | B23: =SUM(综合明细!G95:G99) -> 0 | C23: =SUM(综合明细!H95:H99) -> 167 | D23: =SUM(综合明细!I95:I99) -> 69 | E23: =SUM(B23:D23) -> 236 | F23: =IF(E23=0,0,B23/E23) -> 0 | G23: =IF(E23=0,0,C23/E23) -> 0.70762712
A24: Bankstown | B24: =SUM(综合明细!G100:G104) -> 0 | C24: =SUM(综合明细!H100:H104) -> 144 | D24: =SUM(综合明细!I100:I104) -> 114 | E24: =SUM(B24:D24) -> 258 | F24: =IF(E24=0,0,B24/E24) -> 0 | G24: =IF(E24=0,0,C24/E24) -> 0.55813953
A25: Tuggerah | B25: =SUM(综合明细!G105:G109) -> 0 | C25: =SUM(综合明细!H105:H109) -> 184 | D25: =SUM(综合明细!I105:I109) -> 127 | E25: =SUM(B25:D25) -> 311 | F25: =IF(E25=0,0,B25/E25) -> 0 | G25: =IF(E25=0,0,C25/E25) -> 0.59163987
A26: Kotara | B26: =SUM(综合明细!G110:G114) -> 0 | C26: =SUM(综合明细!H110:H114) -> 386 | D26: =SUM(综合明细!I110:I114) -> 103 | E26: =SUM(B26:D26) -> 489 | F26: =IF(E26=0,0,B26/E26) -> 0 | G26: =IF(E26=0,0,C26/E26) -> 0.78936605
A27: Southport Park | B27: =SUM(综合明细!G115:G119) -> 0 | C27: =SUM(综合明细!H115:H119) -> 107 | D27: =SUM(综合明细!I115:I119) -> 52 | E27: =SUM(B27:D27) -> 159 | F27: =IF(E27=0,0,B27/E27) -> 0 | G27: =IF(E27=0,0,C27/E27) -> 0.67295597
A28: Top Ryde | B28: =SUM(综合明细!G120:G124) -> 0 | C28: =SUM(综合明细!H120:H124) -> 267 | D28: =SUM(综合明细!I120:I124) -> 258 | E28: =SUM(B28:D28) -> 525 | F28: =IF(E28=0,0,B28/E28) -> 0 | G28: =IF(E28=0,0,C28/E28) -> 0.50857143
A29: Discount General Charlestown | B29: =SUM(综合明细!G125:G129) -> 0 | C29: =SUM(综合明细!H125:H129) -> 0 | D29: =SUM(综合明细!I125:I129) -> 0 | E29: =SUM(B29:D29) -> 0 | F29: =IF(E29=0,0,B29/E29) -> 0 | G29: =IF(E29=0,0,C29/E29) -> 0
A30: HB Warehouse | B30: =SUM(综合明细!G130:G134) -> 0 | C30: =SUM(综合明细!H130:H134) -> 0 | D30: =SUM(综合明细!I130:I134) -> 0 | E30: =SUM(B30:D30) -> 0 | F30: =IF(E30=0,0,B30/E30) -> 0 | G30: =IF(E30=0,0,C30/E30) -> 0
A31: 全部分店合计 | B31: =SUM(B5:B30) -> 1601 | C31: =SUM(C5:C30) -> 5462 | D31: =SUM(D5:D30) -> 2354 | E31: =SUM(E5:E30) -> 9417 | F31: =IF(E31=0,0,B31/E31) -> 0.17001168 | G31: =IF(E31=0,0,C31/E31) -> 0.58001487

Sheet 2026进货数量
A1: 2026复活节卡片进货数量
A2: 来源：Art Wrap（IG Design）供应商报表；仅包含5个确认货号。数量为 INVOICE (Quantity)。
A4: 门店名称 | B4: BEAC072 | C4: EA258 | D4: BEAC130 | E4: BEAC071 | F4: EA256 | G4: 门店合计
A5: Robinson Road | B5: 144 | C5: 144 | D5: 144 | E5: 0 | F5: 0 | G5: =SUM(B5:F5) -> 432
A6: Peninsula Fair | B6: 288 | C6: 288 | D6: 144 | E6: 0 | F6: 0 | G6: =SUM(B6:F6) -> 720
A7: Campbelltown | B7: 144 | C7: 432 | D7: 288 | E7: 0 | F7: 0 | G7: =SUM(B7:F7) -> 864
A8: Charlestown Square | B8: 288 | C8: 144 | D8: 288 | E8: 0 | F8: 0 | G8: =SUM(B8:F8) -> 720
A9: Jesmond | B9: 144 | C9: 0 | D9: 288 | E9: 0 | F9: 0 | G9: =SUM(B9:F9) -> 432
A10: Pender Place | B10: 144 | C10: 144 | D10: 0 | E10: 0 | F10: 0 | G10: =SUM(B10:F10) -> 288
A11: Lake Haven | B11: 288 | C11: 288 | D11: 288 | E11: 300 | F11: 0 | G11: =SUM(B11:F11) -> 1164
A12: Forster | B12: 288 | C12: 288 | D12: 0 | E12: 0 | F12: 0 | G12: =SUM(B12:F12) -> 576
A13: Glendale | B13: 288 | C13: 144 | D13: 288 | E13: 0 | F13: 0 | G13: =SUM(B13:F13) -> 720
A14: Orion | B14: 432 | C14: 288 | D14: 432 | E14: 0 | F14: 0 | G14: =SUM(B14:F14) -> 1152
A15: Kawana | B15: 144 | C15: 288 | D15: 288 | E15: 0 | F15: 0 | G15: =SUM(B15:F15) -> 720
A16: Cronulla | B16: 432 | C16: 144 | D16: 288 | E16: 0 | F16: 300 | G16: =SUM(B16:F16) -> 1164
... A30: HB Warehouse | B30: 0 | C30: 288 | D30: 0 | E30: 300 | F30: 0 | G30: =SUM(B30:F30) -> 588
A31: 全部门店合计 | B31: =SUM(B5:B30) -> 5328 | C31: =SUM(C5:C30) -> 4032 | D31: =SUM(D5:D30) -> 5040 | E31: =SUM(E5:E30) -> 1200 | F31: =SUM(F5:F30) -> 600 | G31: =SUM(G5:G30) -> 16200

Sheet 2026供应商退货
A1: 2026复活节卡片供应商退货
A2: 来源：供应商报表 CREDIT (Quantity)；原负数已取绝对值，表内全部以正数表示退回供应商的数量。
A4: 门店名称 | B4: BEAC072 | C4: EA258 | D4: BEAC130 | E4: BEAC071 | F4: EA256 | G4: 门店合计
A5: Robinson Road | B5: 81 | C5: 70 | D5: 100 | E5: 0 | F5: 0 | G5: =SUM(B5:F5) -> 251
A6: Peninsula Fair | B6: 79 | C6: 86 | D6: 0 | E6: 0 | F6: 0 | G6: =SUM(B6:F6) -> 165
A7: Campbelltown | B7: 0 | C7: 125 | D7: 73 | E7: 0 | F7: 0 | G7: =SUM(B7:F7) -> 198
A8: Charlestown Square | B8: 187 | C8: 0 | D8: 99 | E8: 0 | F8: 0 | G8: =SUM(B8:F8) -> 286
A9: Jesmond | B9: 66 | C9: 0 | D9: 126 | E9: 0 | F9: 0 | G9: =SUM(B9:F9) -> 192
A10: Pender Place | B10: 111 | C10: 0 | D10: 0 | E10: 0 | F10: 0 | G10: =SUM(B10:F10) -> 111
A11: Lake Haven | B11: 0 | C11: 178 | D11: 113 | E11: 0 | F11: 0 | G11: =SUM(B11:F11) -> 291
A12: Forster | B12: 0 | C12: 0 | D12: 0 | E12: 0 | F12: 0 | G12: =SUM(B12:F12) -> 0
A13: Glendale | B13: 59 | C13: 0 | D13: 100 | E13: 0 | F13: 0 | G13: =SUM(B13:F13) -> 159
A14: Orion | B14: 306 | C14: 216 | D14: 319 | E14: 0 | F14: 0 | G14: =SUM(B14:F14) -> 841
A15: Kawana | B15: 0 | C15: 0 | D15: 0 | E15: 0 | F15: 0 | G15: =SUM(B15:F15) -> 0
A16: Cronulla | B16: 352 | C16: 128 | D16: 205 | E16: 0 | F16: 0 | G16: =SUM(B16:F16) -> 685
... A30: HB Warehouse | B30: 0 | C30: 0 | D30: 0 | E30: 0 | F30: 0 | G30: =SUM(B30:F30) -> 0
A31: 全部门店合计 | B31: =SUM(B5:B30) -> 1439 | C31: =SUM(C5:C30) -> 803 | D31: =SUM(D5:D30) -> 1322 | E31: =SUM(E5:E30) -> 0 | F31: =SUM(F5:F30) -> 0 | G31: =SUM(G5:G30) -> 3564

Sheet 2026净销售数量
A1: 2026复活节期间净销售数量
A2: HBweb ProductStoreDailySalesStatistic；期间 2026-02-01 至 2026-04-01（含）。已包含顾客退货扣减，不重复减退货。
A4: 门店名称 | B4: BEAC072 | C4: EA258 | D4: BEAC130 | E4: BEAC071 | F4: EA256 | G4: 门店合计
A5: Robinson Road | B5: 45 | C5: 62 | D5: 43 | E5: 0 | F5: 0 | G5: =SUM(B5:F5) -> 150
A6: Peninsula Fair | B6: 207 | C6: 148 | D6: 97 | E6: 0 | F6: 0 | G6: =SUM(B6:F6) -> 452
A7: Campbelltown | B7: 125 | C7: 273 | D7: 167 | E7: 0 | F7: 0 | G7: =SUM(B7:F7) -> 565
A8: Charlestown Square | B8: 116 | C8: 63 | D8: 168 | E8: 0 | F8: 0 | G8: =SUM(B8:F8) -> 347
A9: Jesmond | B9: 65 | C9: 0 | D9: 108 | E9: 0 | F9: 0 | G9: =SUM(B9:F9) -> 173
A10: Pender Place | B10: 126 | C10: 126 | D10: 0 | E10: 0 | F10: 0 | G10: =SUM(B10:F10) -> 252
A11: Lake Haven | B11: 151 | C11: 99 | D11: 132 | E11: 322 | F11: 47 | G11: =SUM(B11:F11) -> 751
A12: Forster | B12: 177 | C12: 113 | D12: 0 | E12: 0 | F12: 0 | G12: =SUM(B12:F12) -> 290
A13: Glendale | B13: 218 | C13: 124 | D13: 161 | E13: 0 | F13: 0 | G13: =SUM(B13:F13) -> 503
A14: Orion | B14: 83 | C14: 83 | D14: 94 | E14: 0 | F14: 0 | G14: =SUM(B14:F14) -> 260
A15: Kawana | B15: 60 | C15: 210 | D15: 169 | E15: 0 | F15: 0 | G15: =SUM(B15:F15) -> 439
A16: Cronulla | B16: 154 | C16: 80 | D16: 120 | E16: 99 | F16: 155 | G16: =SUM(B16:F16) -> 608
... A30: HB Warehouse | B30: 0 | C30: 0 | D30: 0 | E30: 0 | F30: 0 | G30: =SUM(B30:F30) -> 0
A31: 全部门店合计 | B31: =SUM(B5:B30) -> 3067 | C31: =SUM(C5:C30) -> 2391 | D31: =SUM(D5:D30) -> 2354 | E31: =SUM(E5:E30) -> 1285 | F31: =SUM(F5:F30) -> 320 | G31: =SUM(G5:G30) -> 9417

Sheet 2027建议订货量
A1: 2027复活节卡片建议订货量
A2: 门店达到半套销量后按完整包装四舍五入；中央库存补足全公司105%需求缓冲。正式下单前须扣除可销售现存库存。
A4: 门店名称 | B4: BEAC072 | C4: EA258 | D4: BEAC130 | E4: BEAC071 | F4: EA256 | G4: 门店合计
A5: Robinson Road | B5: =IF('2026净销售数量'!B5=0,0,IF('2026净销售数量'!B5<口径与门店映射!$C$5/2,0,ROUND('2026净销售数量'!B5/口径与门店映射!$C$5,0)*口径与门店映射!$C$5)) -> 0 | C5: =IF('2026净销售数量'!C5=0,0,IF('2026净销售数量'!C5<口径与门店映射!$C$6/2,0,ROUND('2026净销售数量'!C5/口径与门店映射!$C$6,0)*口径与门店映射!$C$6)) -> 0 | D5: =IF('2026净销售数量'!D5=0,0,IF('2026净销售数量'!D5<口径与门店映射!$C$7/2,0,ROUND('2026净销售数量'!D5/口径与门店映射!$C$7,0)*口径与门店映射!$C$7)) -> 0 | E5: =IF('2026净销售数量'!E5=0,0,IF('2026净销售数量'!E5<口径与门店映射!$C$8/2,0,ROUND('2026净销售数量'!E5/口径与门店映射!$C$8,0)*口径与门店映射!$C$8)) -> 0 | F5: =IF('2026净销售数量'!F5=0,0,IF('2026净销售数量'!F5<口径与门店映射!$C$9/2,0,ROUND('2026净销售数量'!F5/口径与门店映射!$C$9,0)*口径与门店映射!$C$9)) -> 0 | G5: =SUM(B5:F5) -> 0
A6: Peninsula Fair | B6: =IF('2026净销售数量'!B6=0,0,IF('2026净销售数量'!B6<口径与门店映射!$C$5/2,0,ROUND('2026净销售数量'!B6/口径与门店映射!$C$5,0)*口径与门店映射!$C$5)) -> 144 | C6: =IF('2026净销售数量'!C6=0,0,IF('2026净销售数量'!C6<口径与门店映射!$C$6/2,0,ROUND('2026净销售数量'!C6/口径与门店映射!$C$6,0)*口径与门店映射!$C$6)) -> 144 | D6: =IF('2026净销售数量'!D6=0,0,IF('2026净销售数量'!D6<口径与门店映射!$C$7/2,0,ROUND('2026净销售数量'!D6/口径与门店映射!$C$7,0)*口径与门店映射!$C$7)) -> 144 | E6: =IF('2026净销售数量'!E6=0,0,IF('2026净销售数量'!E6<口径与门店映射!$C$8/2,0,ROUND('2026净销售数量'!E6/口径与门店映射!$C$8,0)*口径与门店映射!$C$8)) -> 0 | F6: =IF('2026净销售数量'!F6=0,0,IF('2026净销售数量'!F6<口径与门店映射!$C$9/2,0,ROUND('2026净销售数量'!F6/口径与门店映射!$C$9,0)*口径与门店映射!$C$9)) -> 0 | G6: =SUM(B6:F6) -> 432
A7: Campbelltown | B7: =IF('2026净销售数量'!B7=0,0,IF('2026净销售数量'!B7<口径与门店映射!$C$5/2,0,ROUND('2026净销售数量'!B7/口径与门店映射!$C$5,0)*口径与门店映射!$C$5)) -> 144 | C7: =IF('2026净销售数量'!C7=0,0,IF('2026净销售数量'!C7<口径与门店映射!$C$6/2,0,ROUND('2026净销售数量'!C7/口径与门店映射!$C$6,0)*口径与门店映射!$C$6)) -> 288 | D7: =IF('2026净销售数量'!D7=0,0,IF('2026净销售数量'!D7<口径与门店映射!$C$7/2,0,ROUND('2026净销售数量'!D7/口径与门店映射!$C$7,0)*口径与门店映射!$C$7)) -> 144 | E7: =IF('2026净销售数量'!E7=0,0,IF('2026净销售数量'!E7<口径与门店映射!$C$8/2,0,ROUND('2026净销售数量'!E7/口径与门店映射!$C$8,0)*口径与门店映射!$C$8)) -> 0 | F7: =IF('2026净销售数量'!F7=0,0,IF('2026净销售数量'!F7<口径与门店映射!$C$9/2,0,ROUND('2026净销售数量'!F7/口径与门店映射!$C$9,0)*口径与门店映射!$C$9)) -> 0 | G7: =SUM(B7:F7) -> 576
A8: Charlestown Square | B8: =IF('2026净销售数量'!B8=0,0,IF('2026净销售数量'!B8<口径与门店映射!$C$5/2,0,ROUND('2026净销售数量'!B8/口径与门店映射!$C$5,0)*口径与门店映射!$C$5)) -> 144 | C8: =IF('2026净销售数量'!C8=0,0,IF('2026净销售数量'!C8<口径与门店映射!$C$6/2,0,ROUND('2026净销售数量'!C8/口径与门店映射!$C$6,0)*口径与门店映射!$C$6)) -> 0 | D8: =IF('2026净销售数量'!D8=0,0,IF('2026净销售数量'!D8<口径与门店映射!$C$7/2,0,ROUND('2026净销售数量'!D8/口径与门店映射!$C$7,0)*口径与门店映射!$C$7)) -> 144 | E8: =IF('2026净销售数量'!E8=0,0,IF('2026净销售数量'!E8<口径与门店映射!$C$8/2,0,ROUND('2026净销售数量'!E8/口径与门店映射!$C$8,0)*口径与门店映射!$C$8)) -> 0 | F8: =IF('2026净销售数量'!F8=0,0,IF('2026净销售数量'!F8<口径与门店映射!$C$9/2,0,ROUND('2026净销售数量'!F8/口径与门店映射!$C$9,0)*口径与门店映射!$C$9)) -> 0 | G8: =SUM(B8:F8) -> 288
A9: Jesmond | B9: =IF('2026净销售数量'!B9=0,0,IF('2026净销售数量'!B9<口径与门店映射!$C$5/2,0,ROUND('2026净销售数量'!B9/口径与门店映射!$C$5,0)*口径与门店映射!$C$5)) -> 0 | C9: =IF('2026净销售数量'!C9=0,0,IF('2026净销售数量'!C9<口径与门店映射!$C$6/2,0,ROUND('2026净销售数量'!C9/口径与门店映射!$C$6,0)*口径与门店映射!$C$6)) -> 0 | D9: =IF('2026净销售数量'!D9=0,0,IF('2026净销售数量'!D9<口径与门店映射!$C$7/2,0,ROUND('2026净销售数量'!D9/口径与门店映射!$C$7,0)*口径与门店映射!$C$7)) -> 144 | E9: =IF('2026净销售数量'!E9=0,0,IF('2026净销售数量'!E9<口径与门店映射!$C$8/2,0,ROUND('2026净销售数量'!E9/口径与门店映射!$C$8,0)*口径与门店映射!$C$8)) -> 0 | F9: =IF('2026净销售数量'!F9=0,0,IF('2026净销售数量'!F9<口径与门店映射!$C$9/2,0,ROUND('2026净销售数量'!F9/口径与门店映射!$C$9,0)*口径与门店映射!$C$9)) -> 0 | G9: =SUM(B9:F9) -> 144
A10: Pender Place | B10: =IF('2026净销售数量'!B10=0,0,IF('2026净销售数量'!B10<口径与门店映射!$C$5/2,0,ROUND('2026净销售数量'!B10/口径与门店映射!$C$5,0)*口径与门店映射!$C$5)) -> 144 | C10: =IF('2026净销售数量'!C10=0,0,IF('2026净销售数量'!C10<口径与门店映射!$C$6/2,0,ROUND('2026净销售数量'!C10/口径与门店映射!$C$6,0)*口径与门店映射!$C$6)) -> 144 | D10: =IF('2026净销售数量'!D10=0,0,IF('2026净销售数量'!D10<口径与门店映射!$C$7/2,0,ROUND('2026净销售数量'!D10/口径与门店映射!$C$7,0)*口径与门店映射!$C$7)) -> 0 | E10: =IF('2026净销售数量'!E10=0,0,IF('2026净销售数量'!E10<口径与门店映射!$C$8/2,0,ROUND('2026净销售数量'!E10/口径与门店映射!$C$8,0)*口径与门店映射!$C$8)) -> 0 | F10: =IF('2026净销售数量'!F10=0,0,IF('2026净销售数量'!F10<口径与门店映射!$C$9/2,0,ROUND('2026净销售数量'!F10/口径与门店映射!$C$9,0)*口径与门店映射!$C$9)) -> 0 | G10: =SUM(B10:F10) -> 288
A11: Lake Haven | B11: =IF('2026净销售数量'!B11=0,0,IF('2026净销售数量'!B11<口径与门店映射!$C$5/2,0,ROUND('2026净销售数量'!B11/口径与门店映射!$C$5,0)*口径与门店映射!$C$5)) -> 144 | C11: =IF('2026净销售数量'!C11=0,0,IF('2026净销售数量'!C11<口径与门店映射!$C$6/2,0,ROUND('2026净销售数量'!C11/口径与门店映射!$C$6,0)*口径与门店映射!$C$6)) -> 144 | D11: =IF('2026净销售数量'!D11=0,0,IF('2026净销售数量'!D11<口径与门店映射!$C$7/2,0,ROUND('2026净销售数量'!D11/口径与门店映射!$C$7,0)*口径与门店映射!$C$7)) -> 144 | E11: =IF('2026净销售数量'!E11=0,0,IF('2026净销售数量'!E11<口径与门店映射!$C$8/2,0,ROUND('2026净销售数量'!E11/口径与门店映射!$C$8,0)*口径与门店映射!$C$8)) -> 300 | F11: =IF('2026净销售数量'!F11=0,0,IF('2026净销售数量'!F11<口径与门店映射!$C$9/2,0,ROUND('2026净销售数量'!F11/口径与门店映射!$C$9,0)*口径与门店映射!$C$9)) -> 0 | G11: =SUM(B11:F11) -> 732
A12: Forster | B12: =IF('2026净销售数量'!B12=0,0,IF('2026净销售数量'!B12<口径与门店映射!$C$5/2,0,ROUND('2026净销售数量'!B12/口径与门店映射!$C$5,0)*口径与门店映射!$C$5)) -> 144 | C12: =IF('2026净销售数量'!C12=0,0,IF('2026净销售数量'!C12<口径与门店映射!$C$6/2,0,ROUND('2026净销售数量'!C12/口径与门店映射!$C$6,0)*口径与门店映射!$C$6)) -> 144 | D12: =IF('2026净销售数量'!D12=0,0,IF('2026净销售数量'!D12<口径与门店映射!$C$7/2,0,ROUND('2026净销售数量'!D12/口径与门店映射!$C$7,0)*口径与门店映射!$C$7)) -> 0 | E12: =IF('2026净销售数量'!E12=0,0,IF('2026净销售数量'!E12<口径与门店映射!$C$8/2,0,ROUND('2026净销售数量'!E12/口径与门店映射!$C$8,0)*口径与门店映射!$C$8)) -> 0 | F12: =IF('2026净销售数量'!F12=0,0,IF('2026净销售数量'!F12<口径与门店映射!$C$9/2,0,ROUND('2026净销售数量'!F12/口径与门店映射!$C$9,0)*口径与门店映射!$C$9)) -> 0 | G12: =SUM(B12:F12) -> 288
A13: Glendale | B13: =IF('2026净销售数量'!B13=0,0,IF('2026净销售数量'!B13<口径与门店映射!$C$5/2,0,ROUND('2026净销售数量'!B13/口径与门店映射!$C$5,0)*口径与门店映射!$C$5)) -> 288 | C13: =IF('2026净销售数量'!C13=0,0,IF('2026净销售数量'!C13<口径与门店映射!$C$6/2,0,ROUND('2026净销售数量'!C13/口径与门店映射!$C$6,0)*口径与门店映射!$C$6)) -> 144 | D13: =IF('2026净销售数量'!D13=0,0,IF('2026净销售数量'!D13<口径与门店映射!$C$7/2,0,ROUND('2026净销售数量'!D13/口径与门店映射!$C$7,0)*口径与门店映射!$C$7)) -> 144 | E13: =IF('2026净销售数量'!E13=0,0,IF('2026净销售数量'!E13<口径与门店映射!$C$8/2,0,ROUND('2026净销售数量'!E13/口径与门店映射!$C$8,0)*口径与门店映射!$C$8)) -> 0 | F13: =IF('2026净销售数量'!F13=0,0,IF('2026净销售数量'!F13<口径与门店映射!$C$9/2,0,ROUND('2026净销售数量'!F13/口径与门店映射!$C$9,0)*口径与门店映射!$C$9)) -> 0 | G13: =SUM(B13:F13) -> 576
A14: Orion | B14: =IF('2026净销售数量'!B14=0,0,IF('2026净销售数量'!B14<口径与门店映射!$C$5/2,0,ROUND('2026净销售数量'!B14/口径与门店映射!$C$5,0)*口径与门店映射!$C$5)) -> 144 | C14: =IF('2026净销售数量'!C14=0,0,IF('2026净销售数量'!C14<口径与门店映射!$C$6/2,0,ROUND('2026净销售数量'!C14/口径与门店映射!$C$6,0)*口径与门店映射!$C$6)) -> 144 | D14: =IF('2026净销售数量'!D14=0,0,IF('2026净销售数量'!D14<口径与门店映射!$C$7/2,0,ROUND('2026净销售数量'!D14/口径与门店映射!$C$7,0)*口径与门店映射!$C$7)) -> 144 | E14: =IF('2026净销售数量'!E14=0,0,IF('2026净销售数量'!E14<口径与门店映射!$C$8/2,0,ROUND('2026净销售数量'!E14/口径与门店映射!$C$8,0)*口径与门店映射!$C$8)) -> 0 | F14: =IF('2026净销售数量'!F14=0,0,IF('2026净销售数量'!F14<口径与门店映射!$C$9/2,0,ROUND('2026净销售数量'!F14/口径与门店映射!$C$9,0)*口径与门店映射!$C$9)) -> 0 | G14: =SUM(B14:F14) -> 432
A15: Kawana | B15: =IF('2026净销售数量'!B15=0,0,IF('2026净销售数量'!B15<口径与门店映射!$C$5/2,0,ROUND('2026净销售数量'!B15/口径与门店映射!$C$5,0)*口径与门店映射!$C$5)) -> 0 | C15: =IF('2026净销售数量'!C15=0,0,IF('2026净销售数量'!C15<口径与门店映射!$C$6/2,0,ROUND('2026净销售数量'!C15/口径与门店映射!$C$6,0)*口径与门店映射!$C$6)) -> 144 | D15: =IF('2026净销售数量'!D15=0,0,IF('2026净销售数量'!D15<口径与门店映射!$C$7/2,0,ROUND('2026净销售数量'!D15/口径与门店映射!$C$7,0)*口径与门店映射!$C$7)) -> 144 | E15: =IF('2026净销售数量'!E15=0,0,IF('2026净销售数量'!E15<口径与门店映射!$C$8/2,0,ROUND('2026净销售数量'!E15/口径与门店映射!$C$8,0)*口径与门店映射!$C$8)) -> 0 | F15: =IF('2026净销售数量'!F15=0,0,IF('2026净销售数量'!F15<口径与门店映射!$C$9/2,0,ROUND('2026净销售数量'!F15/口径与门店映射!$C$9,0)*口径与门店映射!$C$9)) -> 0 | G15: =SUM(B15:F15) -> 288
A16: Cronulla | B16: =IF('2026净销售数量'!B16=0,0,IF('2026净销售数量'!B16<口径与门店映射!$C$5/2,0,ROUND('2026净销售数量'!B16/口径与门店映射!$C$5,0)*口径与门店映射!$C$5)) -> 144 | C16: =IF('2026净销售数量'!C16=0,0,IF('2026净销售数量'!C16<口径与门店映射!$C$6/2,0,ROUND('2026净销售数量'!C16/口径与门店映射!$C$6,0)*口径与门店映射!$C$6)) -> 144 | D16: =IF('2026净销售数量'!D16=0,0,IF('2026净销售数量'!D16<口径与门店映射!$C$7/2,0,ROUND('2026净销售数量'!D16/口径与门店映射!$C$7,0)*口径与门店映射!$C$7)) -> 144 | E16: =IF('2026净销售数量'!E16=0,0,IF('2026净销售数量'!E16<口径与门店映射!$C$8/2,0,ROUND('2026净销售数量'!E16/口径与门店映射!$C$8,0)*口径与门店映射!$C$8)) -> 0 | F16: =IF('2026净销售数量'!F16=0,0,IF('2026净销售数量'!F16<口径与门店映射!$C$9/2,0,ROUND('2026净销售数量'!F16/口径与门店映射!$C$9,0)*口径与门店映射!$C$9)) -> 300 | G16: =SUM(B16:F16) -> 732
... A28: Top Ryde | B28: =IF('2026净销售数量'!B28=0,0,IF('2026净销售数量'!B28<口径与门店映射!$C$5/2,0,ROUND('2026净销售数量'!B28/口径与门店映射!$C$5,0)*口径与门店映射!$C$5)) -> 288 | C28: =IF('2026净销售数量'!C28=0,0,IF('2026净销售数量'!C28<口径与门店映射!$C$6/2,0,ROUND('2026净销售数量'!C28/口径与门店映射!$C$6,0)*口径与门店映射!$C$6)) -> 0 | D28: =IF('2026净销售数量'!D28=0,0,IF('2026净销售数量'!D28<口径与门店映射!$C$7/2,0,ROUND('2026净销售数量'!D28/口径与门店映射!$C$7,0)*口径与门店映射!$C$7)) -> 288 | E28: =IF('2026净销售数量'!E28=0,0,IF('2026净销售数量'!E28<口径与门店映射!$C$8/2,0,ROUND('2026净销售数量'!E28/口径与门店映射!$C$8,0)*口径与门店映射!$C$8)) -> 0 | F28: =IF('2026净销售数量'!F28=0,0,IF('2026净销售数量'!F28<口径与门店映射!$C$9/2,0,ROUND('2026净销售数量'!F28/口径与门店映射!$C$9,0)*口径与门店映射!$C$9)) -> 0 | G28: =SUM(B28:F28) -> 576
A29: Discount General Charlestown | G29: =SUM(B29:F29) -> 0
A30: HB Warehouse | B30: =MAX(0,ROUNDUP((SUM('2026净销售数量'!B$5:B$29)*口径与门店映射!$L$2-SUM(B$5:B$29))/口径与门店映射!$C$5,0)*口径与门店映射!$C$5) -> 288 | C30: =MAX(0,ROUNDUP((SUM('2026净销售数量'!C$5:C$29)*口径与门店映射!$L$2-SUM(C$5:C$29))/口径与门店映射!$C$6,0)*口径与门店映射!$C$6) -> 0 | D30: =MAX(0,ROUNDUP((SUM('2026净销售数量'!D$5:D$29)*口径与门店映射!$L$2-SUM(D$5:D$29))/口径与门店映射!$C$7,0)*口径与门店映射!$C$7) -> 144 | E30: =MAX(0,ROUNDUP((SUM('2026净销售数量'!E$5:E$29)*口径与门店映射!$L$2-SUM(E$5:E$29))/口径与门店映射!$C$8,0)*口径与门店映射!$C$8) -> 300 | F30: =MAX(0,ROUNDUP((SUM('2026净销售数量'!F$5:F$29)*口径与门店映射!$L$2-SUM(F$5:F$29))/口径与门店映射!$C$9,0)*口径与门店映射!$C$9) -> 300 | G30: =SUM(B30:F30) -> 1032
A31: 全部门店合计 | B31: =SUM(B5:B30) -> 3312 | C31: =SUM(C5:C30) -> 2592 | D31: =SUM(D5:D30) -> 2592 | E31: =SUM(E5:E30) -> 1500 | F31: =SUM(F5:F30) -> 600 | G31: =SUM(G5:G30) -> 10596

Sheet 建议原因
A1: 2027复活节卡片订货建议原因
A2: 每个单元格对应门店与货号；“退货率较高”按货号整体供应商退货率判断。未映射对象不自动给数量。
A4: 门店名称 | B4: BEAC072 | C4: EA258 | D4: BEAC130 | E4: BEAC071 | F4: EA256
A5: Robinson Road | B5: 净销量45，不足半套72；建议0，由中央库存补货；2026退供应商81张（视为季后库存）；该货号整体退货率≥20%，谨慎减量 | C5: 净销量62，不足半套72；建议0，由中央库存补货；2026退供应商70张（视为季后库存） | D5: 净销量43，不足半套72；建议0，由中央库存补货；2026退供应商100张（视为季后库存）；该货号整体退货率≥20%，谨慎减量 | E5: 无净销量，建议0；先查现存库存及扫码映射 | F5: 无净销量，建议0；先查现存库存及扫码映射
A6: Peninsula Fair | B6: 按净销量207及包装规格，建议从2026进货288降至144；2026退供应商79张（视为季后库存）；该货号整体退货率≥20%，谨慎减量 | C6: 按净销量148及包装规格，建议从2026进货288降至144；2026退供应商86张（视为季后库存） | D6: 净销量97支持维持2026进货量；建议144；该货号整体退货率≥20%，谨慎减量 | E6: 无净销量，建议0；先查现存库存及扫码映射 | F6: 无净销量，建议0；先查现存库存及扫码映射
A7: Campbelltown | B7: 净销量125支持维持2026进货量；建议144；该货号整体退货率≥20%，谨慎减量 | C7: 按净销量273及包装规格，建议从2026进货432降至288；2026退供应商125张（视为季后库存） | D7: 按净销量167及包装规格，建议从2026进货288降至144；2026退供应商73张（视为季后库存）；该货号整体退货率≥20%，谨慎减量 | E7: 无净销量，建议0；先查现存库存及扫码映射 | F7: 无净销量，建议0；先查现存库存及扫码映射
A8: Charlestown Square | B8: 按净销量116及包装规格，建议从2026进货288降至144；2026退供应商187张（视为季后库存）；该货号整体退货率≥20%，谨慎减量 | C8: 净销量63，不足半套72；建议0，由中央库存补货 | D8: 按净销量168及包装规格，建议从2026进货288降至144；2026退供应商99张（视为季后库存）；该货号整体退货率≥20%，谨慎减量 | E8: 无净销量，建议0；先查现存库存及扫码映射 | F8: 无净销量，建议0；先查现存库存及扫码映射
A9: Jesmond | B9: 净销量65，不足半套72；建议0，由中央库存补货；2026退供应商66张（视为季后库存）；该货号整体退货率≥20%，谨慎减量 | C9: 无净销量，建议0；先查现存库存及扫码映射 | D9: 按净销量108及包装规格，建议从2026进货288降至144；2026退供应商126张（视为季后库存）；该货号整体退货率≥20%，谨慎减量 | E9: 无净销量，建议0；先查现存库存及扫码映射 | F9: 无净销量，建议0；先查现存库存及扫码映射
A10: Pender Place | B10: 净销量126支持维持2026进货量；建议144；2026退供应商111张（视为季后库存）；该货号整体退货率≥20%，谨慎减量 | C10: 净销量126支持维持2026进货量；建议144 | D10: 无净销量，建议0；先查现存库存及扫码映射；该货号整体退货率≥20%，谨慎减量 | E10: 无净销量，建议0；先查现存库存及扫码映射 | F10: 无净销量，建议0；先查现存库存及扫码映射
A11: Lake Haven | B11: 按净销量151及包装规格，建议从2026进货288降至144；该货号整体退货率≥20%，谨慎减量 | C11: 按净销量99及包装规格，建议从2026进货288降至144；2026退供应商178张（视为季后库存） | D11: 按净销量132及包装规格，建议从2026进货288降至144；2026退供应商113张（视为季后库存）；该货号整体退货率≥20%，谨慎减量 | E11: 净销量322支持维持2026进货量；建议300 | F11: 净销量47，不足半套150；建议0，由中央库存补货
A12: Forster | B12: 按净销量177及包装规格，建议从2026进货288降至144；该货号整体退货率≥20%，谨慎减量 | C12: 按净销量113及包装规格，建议从2026进货288降至144 | D12: 无净销量，建议0；先查现存库存及扫码映射；该货号整体退货率≥20%，谨慎减量 | E12: 无净销量，建议0；先查现存库存及扫码映射 | F12: 无净销量，建议0；先查现存库存及扫码映射
A13: Glendale | B13: 净销量218支持维持2026进货量；建议288；2026退供应商59张（视为季后库存）；该货号整体退货率≥20%，谨慎减量 | C13: 净销量124支持维持2026进货量；建议144 | D13: 按净销量161及包装规格，建议从2026进货288降至144；2026退供应商100张（视为季后库存）；该货号整体退货率≥20%，谨慎减量 | E13: 无净销量，建议0；先查现存库存及扫码映射 | F13: 无净销量，建议0；先查现存库存及扫码映射
A14: Orion | B14: 按净销量83及包装规格，建议从2026进货432降至144；2026退供应商306张（视为季后库存）；该货号整体退货率≥20%，谨慎减量 | C14: 按净销量83及包装规格，建议从2026进货288降至144；2026退供应商216张（视为季后库存） | D14: 按净销量94及包装规格，建议从2026进货432降至144；2026退供应商319张（视为季后库存）；该货号整体退货率≥20%，谨慎减量 | E14: 无净销量，建议0；先查现存库存及扫码映射 | F14: 无净销量，建议0；先查现存库存及扫码映射
A15: Kawana | B15: 净销量60，不足半套72；建议0，由中央库存补货；该货号整体退货率≥20%，谨慎减量 | C15: 按净销量210及包装规格，建议从2026进货288降至144 | D15: 按净销量169及包装规格，建议从2026进货288降至144；该货号整体退货率≥20%，谨慎减量 | E15: 无净销量，建议0；先查现存库存及扫码映射 | F15: 无净销量，建议0；先查现存库存及扫码映射
... A30: HB Warehouse | B30: 中央机动库存：补足全公司105%需求，建议 288 | C30: 门店完整包装已覆盖105%需求，无需额外中央库存 | D30: 中央机动库存：补足全公司105%需求，建议 144 | E30: 中央机动库存：补足全公司105%需求，建议 300 | F30: 中央机动库存：补足全公司105%需求，建议 300

Sheet 口径与门店映射
A1: 复活节卡片分析口径、货号汇总与门店映射 | K1: 模型参数
A2: 仅分析 BEAC072、EA258、BEAC130、BEAC071、EA256；BEAC071 已明确确认为复活节卡。 | K2: 中央库存需求系数 | L2: 1.05
A4: 货号 | B4: 商品名称 | C4: 包装量 | D4: 2026进货 | E4: 供应商退货 | F4: 净销量 | G4: 退货率 | H4: 2027建议 | I4: 较2026进货变化
A5: BEAC072 | B5: Deluxe Easter Card Stand 144 Pieces | C5: 144 | D5: ='2026进货数量'!B31 -> 5328 | E5: ='2026供应商退货'!B31 -> 1439 | F5: ='2026净销售数量'!B31 -> 3067 | G5: =IF(D5=0,0,E5/D5) -> 0.27008258 | H5: ='2027建议订货量'!B31 -> 3312 | I5: =IF(D5=0,0,H5/D5-1) -> -0.37837838
A6: EA258 | B6: World Greetings Easter Card Stand 144 Pieces | C6: 144 | D6: ='2026进货数量'!C31 -> 4032 | E6: ='2026供应商退货'!C31 -> 803 | F6: ='2026净销售数量'!C31 -> 2391 | G6: =IF(D6=0,0,E6/D6) -> 0.19915675 | H6: ='2027建议订货量'!C31 -> 2592 | I6: =IF(D6=0,0,H6/D6-1) -> -0.35714286
A7: BEAC130 | B7: Elegance Easter Card Stand 144 Pieces | C7: 144 | D7: ='2026进货数量'!D31 -> 5040 | E7: ='2026供应商退货'!D31 -> 1322 | F7: ='2026净销售数量'!D31 -> 2354 | G7: =IF(D7=0,0,E7/D7) -> 0.26230159 | H7: ='2027建议订货量'!D31 -> 2592 | I7: =IF(D7=0,0,H7/D7-1) -> -0.48571429
A8: BEAC071 | B8: Apsley Easter Card Stand 300 Pieces | C8: 300 | D8: ='2026进货数量'!E31 -> 1200 | E8: ='2026供应商退货'!E31 -> 0 | F8: ='2026净销售数量'!E31 -> 1285 | G8: =IF(D8=0,0,E8/D8) -> 0 | H8: ='2027建议订货量'!E31 -> 1500 | I8: =IF(D8=0,0,H8/D8-1) -> 0.25
A9: EA256 | B9: Jordan Easter Card Stand 300 Pieces | C9: 300 | D9: ='2026进货数量'!F31 -> 600 | E9: ='2026供应商退货'!F31 -> 0 | F9: ='2026净销售数量'!F31 -> 320 | G9: =IF(D9=0,0,E9/D9) -> 0 | H9: ='2027建议订货量'!F31 -> 600 | I9: =IF(D9=0,0,H9/D9-1) -> 0
A10: 全部货号合计 | D10: =SUM(D5:D9) -> 16200 | E10: =SUM(E5:E9) -> 3564 | F10: =SUM(F5:F9) -> 9417 | G10: =IF(D10=0,0,E10/D10) -> 0.22 | H10: =SUM(H5:H9) -> 10596 | I10: =IF(D10=0,0,H10/D10-1) -> -0.34592593
A13: 供应商客户代码 | B13: 供应商客户名称 | C13: 标准门店名称 | D13: HBweb门店代码 | E13: 映射状态 | G13: 口径与订货规则
A14: HOTROB | B14: HOT BARGAIN ROBINSON ROAD | C14: Robinson Road | D14: 1002 | E14: 已映射 | G14: 销售期间 | H14: 2026-02-01 至 2026-04-01（含）
A15: HOTPEN | B15: HOT BARGAIN PENINSULA FAIR | C15: Peninsula Fair | D15: 1003 | E15: 已映射 | G15: 供应商期间 | H15: 原报表：Sep 2025 至 May 2026
A16: HOTCAMB | B16: HOT BARGAIN CAMPBELLTOWN MALL | C16: Campbelltown | D16: 1004 | E16: 已映射 | G16: 净销量口径 | H16: HBweb商品日统计；已包含顾客退货扣减
A17: HOTCHL | B17: HOT BARGAIN CHARLESTOWN SQUARE | C17: Charlestown Square | D17: 1005 | E17: 已映射 | G17: 直接订货 | H17: 销量不足半套为0；否则按完整包装四舍五入
A18: HOTBJE | B18: HOT BARGAIN | C18: Jesmond | D18: 1007 | E18: 已映射 | G18: 中央库存 | H18: 补足全公司净销量的105%，按完整包装向上取整
A19: HOTMAT | B19: HOT BARGAIN MAITLAND | C19: Pender Place | D19: 1008 | E19: 已映射 | G19: 高退货提示 | H19: 货号整体供应商退货率达到20%时提示谨慎减量
A20: HOTLAK | B20: HOT BARGAIN LAKE HAVEN | C20: Lake Haven | D20: 1009 | E20: 已映射 | G20: 未映射对象 | H20: Discount General Charlestown 人工核对；PARTY GO 已映射至 Bankstown（1024）
A21: HOTFST | B21: HOT BARGAIN FORSTER | C21: Forster | D21: 1011 | E21: 已映射 | G21: 库存限制 | H21: 建议为订货基准，正式下单前须扣除可销售现存库存
A22: HOTGLN | B22: HOT BARGAIN GLENDALE | C22: Glendale | D22: 1012 | E22: 已映射 | G22: 数据一致性 | H22: 附件文本与原Excel共81行，逐行数量零差异
A23: HOTSPR | B23: HOT BARGAIN SPRINGFIELD | C23: Orion | D23: 1013 | E23: 已映射
A24: HOTKAW | B24: HOT BARGAIN KAWANA | C24: Kawana | D24: 1014 | E24: 已映射
A25: HOTBCR | B25: HOT BARGAIN CRONULLA | C25: Cronulla | D25: 1015 | E25: 已映射
A26: HOTGRE | B26: HOT BARGAIN GREENHILLS | C26: Greenhills | D26: 1016 | E26: 已映射
A27: HOTBAWA | B27: HOT BARGAIN WARATAH | C27: Waratah | D27: 1017 | E27: 已映射
A28: HOTTOU | B28: HOT BARGAIN TOUKLEY | C28: Toukley | D28: 1018 | E28: 已映射
A29: HOTWBA | B29: HOT BARGAIN WARNERS BAY | C29: Warners Bay | D29: 1019 | E29: 已映射
A30: HOTBWA | B30: HOT BARGAIN WALLSEND | C30: Wallsend | D30: 1020 | E30: 已映射
A31: SAVVYS | B31: SAVVY SAVE ORAN PARK | C31: Oran Park | D31: 1023 | E31: 已映射
A32: HOTKOR | B32: HOT BARGAIN KOTARA | C32: Kotara | D32: 1028 | E32: 已映射
A33: HOTSTH | B33: HOT BARGAIN SOUTHPORT PARK | C33: Southport Park | D33: 1031 | E33: 已映射
A34: HOTTPR | B34: HOT BARGAIN TOP RYDE | C34: Top Ryde | D34: 1033 | E34: 已映射
A35: DISCHL | B35: DISCOUNT GENERAL CHARLESTOWN | C35: Discount General Charlestown | E35: 未映射，人工核对
A36: PARTGO | B36: PARTY GO | C36: Bankstown | D36: 1024 | E36: 已映射
A37: HOBRTC | B37: HOT BARGAIN AUSTRALIAN PTY LTD | C37: HB Warehouse | D37: 1006 | E37: 中央库存
